Workbook

Sheet المخزن
A1: المخزن - كشف الأصناف وحركة البيع/المرتجع لكل عميل (تلقائي)
A2: الكود | B2: 4K حموده | C2: مكتب القاضي | D2: الاتشو | E2: علاء بوم ارض النت | F2: كيمو ميت ابو خالد | G2: KAZO | H2: LAFY | I2: POINT زفتي (جديد) | J2: POINT سعد زغلول (قديم) | K2: POWER ارض النت | L2: POWER زفتي | M2: احمد المنوفي | N2: السفير | O2: العالمي | P2: باهي التركي | Q2: توتي دماص | R2: رضا محمد | S2: زومبي العشري | T2: محمد عرابي | U2: عم جمال | V2: فاير سيليكت | W2: فرانكو | X2: كريم بكر | Y2: بفرا | Z2: محل كوم النور | AA2: محمد النجار | AB2: محمود عبدالرسول | AC2: مول المصطفي | AD2: مصانع | AE2: صافي المباع (تلقائي) | AF2: الصنف | AG2: عدد الموديل (الرصيد الوارد) | AH2: الباقي (تلقائي) | AI2: سعر البيع | AJ2: قيمة بضاعة المخزن (تلقائي)
A3: B01 | B3: =IF($A3="","",SUMIFS('4K حموده'!$D:$D,'4K حموده'!$C:$C,$A3,'4K حموده'!$F:$F,"<>")-SUMIFS('4K حموده'!$D:$D,'4K حموده'!$C:$C,$A3,'4K حموده'!$G:$G,"<>",'4K حموده'!$F:$F,"")) -> 0 | C3: =IF($A3="","",SUMIFS('مكتب القاضي'!$D:$D,'مكتب القاضي'!$C:$C,$A3,'مكتب القاضي'!$F:$F,"<>")-SUMIFS('مكتب القاضي'!$D:$D,'مكتب القاضي'!$C:$C,$A3,'مكتب القاضي'!$G:$G,"<>",'مكتب القاضي'!$F:$F,"")) -> 21 | D3: =IF($A3="","",SUMIFS(الاتشو!$D:$D,الاتشو!$C:$C,$A3,الاتشو!$F:$F,"<>")-SUMIFS(الاتشو!$D:$D,الاتشو!$C:$C,$A3,الاتشو!$G:$G,"<>",الاتشو!$F:$F,"")) -> 0 | E3: =IF($A3="","",SUMIFS('علاء بوم ارض النت'!$D:$D,'علاء بوم ارض النت'!$C:$C,$A3,'علاء بوم ارض النت'!$F:$F,"<>")-SUMIFS('علاء بوم ارض النت'!$D:$D,'علاء بوم ارض النت'!$C:$C,$A3,'علاء بوم ارض النت'!$G:$G,"<>",'علاء بوم ارض النت'!$F:$F,"")) -> 4 | F3: =IF($A3="","",SUMIFS('كيمو ميت ابو خالد'!$D:$D,'كيمو ميت ابو خالد'!$C:$C,$A3,'كيمو ميت ابو خالد'!$F:$F,"<>")-SUMIFS('كيمو ميت ابو خالد'!$D:$D,'كيمو ميت ابو خالد'!$C:$C,$A3,'كيمو ميت ابو خالد'!$G:$G,"<>",'كيمو ميت ابو خالد'!$F:$F,"")) -> 0 | G3: =IF($A3="","",SUMIFS(KAZO!$D:$D,KAZO!$C:$C,$A3,KAZO!$F:$F,"<>")-SUMIFS(KAZO!$D:$D,KAZO!$C:$C,$A3,KAZO!$G:$G,"<>",KAZO!$F:$F,"")) -> 0 | H3: =IF($A3="","",SUMIFS(LAFY!$D:$D,LAFY!$C:$C,$A3,LAFY!$F:$F,"<>")-SUMIFS(LAFY!$D:$D,LAFY!$C:$C,$A3,LAFY!$G:$G,"<>",LAFY!$F:$F,"")) -> 0 | I3: =IF($A3="","",SUMIFS('POINT زفتي (جديد)'!$D:$D,'POINT زفتي (جديد)'!$C:$C,$A3,'POINT زفتي (جديد)'!$F:$F,"<>")-SUMIFS('POINT زفتي (جديد)'!$D:$D,'POINT زفتي (جديد)'!$C:$C,$A3,'POINT زفتي (جديد)'!$G:$G,"<>",'POINT زفتي (جديد)'!$F:$F,"")) -> 6 | J3: =IF($A3="","",SUMIFS('POINT سعد زغلول (قديم)'!$D:$D,'POINT سعد زغلول (قديم)'!$C:$C,$A3,'POINT سعد زغلول (قديم)'!$F:$F,"<>")-SUMIFS('POINT سعد زغلول (قديم)'!$D:$D,'POINT سعد زغلول (قديم)'!$C:$C,$A3,'POINT سعد زغلول (قديم)'!$G:$G,"<>",'POINT سعد زغلول (قديم)'!$F:$F,"")) -> 0 | K3: =IF($A3="","",SUMIFS('POWER ارض النت'!$D:$D,'POWER ارض النت'!$C:$C,$A3,'POWER ارض النت'!$F:$F,"<>")-SUMIFS('POWER ارض النت'!$D:$D,'POWER ارض النت'!$C:$C,$A3,'POWER ارض النت'!$G:$G,"<>",'POWER ارض النت'!$F:$F,"")) -> 0 | L3: =IF($A3="","",SUMIFS('POWER زفتي'!$D:$D,'POWER زفتي'!$C:$C,$A3,'POWER زفتي'!$F:$F,"<>")-SUMIFS('POWER زفتي'!$D:$D,'POWER زفتي'!$C:$C,$A3,'POWER زفتي'!$G:$G,"<>",'POWER زفتي'!$F:$F,"")) -> 0 | M3: =IF($A3="","",SUMIFS('احمد المنوفي'!$D:$D,'احمد المنوفي'!$C:$C,$A3,'احمد المنوفي'!$F:$F,"<>")-SUMIFS('احمد المنوفي'!$D:$D,'احمد المنوفي'!$C:$C,$A3,'احمد المنوفي'!$G:$G,"<>",'احمد المنوفي'!$F:$F,"")) -> 0 | N3: =IF($A3="","",SUMIFS(السفير!$D:$D,السفير!$C:$C,$A3,السفير!$F:$F,"<>")-SUMIFS(السفير!$D:$D,السفير!$C:$C,$A3,السفير!$G:$G,"<>",السفير!$F:$F,"")) -> 24 | O3: =IF($A3="","",SUMIFS(العالمي!$D:$D,العالمي!$C:$C,$A3,العالمي!$F:$F,"<>")-SUMIFS(العالمي!$D:$D,العالمي!$C:$C,$A3,العالمي!$G:$G,"<>",العالمي!$F:$F,"")) -> 0 | P3: =IF($A3="","",SUMIFS('باهي التركي'!$D:$D,'باهي التركي'!$C:$C,$A3,'باهي التركي'!$F:$F,"<>")-SUMIFS('باهي التركي'!$D:$D,'باهي التركي'!$C:$C,$A3,'باهي التركي'!$G:$G,"<>",'باهي التركي'!$F:$F,"")) -> 24 | Q3: =IF($A3="","",SUMIFS('توتي دماص'!$D:$D,'توتي دماص'!$C:$C,$A3,'توتي دماص'!$F:$F,"<>")-SUMIFS('توتي دماص'!$D:$D,'توتي دماص'!$C:$C,$A3,'توتي دماص'!$G:$G,"<>",'توتي دماص'!$F:$F,"")) -> 0 | R3: =IF($A3="","",SUMIFS('رضا محمد'!$D:$D,'رضا محمد'!$C:$C,$A3,'رضا محمد'!$F:$F,"<>")-SUMIFS('رضا محمد'!$D:$D,'رضا محمد'!$C:$C,$A3,'رضا محمد'!$G:$G,"<>",'رضا محمد'!$F:$F,"")) -> 0 | S3: =IF($A3="","",SUMIFS('زومبي العشري'!$D:$D,'زومبي العشري'!$C:$C,$A3,'زومبي العشري'!$F:$F,"<>")-SUMIFS('زومبي العشري'!$D:$D,'زومبي العشري'!$C:$C,$A3,'زومبي العشري'!$G:$G,"<>",'زومبي العشري'!$F:$F,"")) -> 0 | T3: =IF($A3="","",SUMIFS('محمد عرابي'!$D:$D,'محمد عرابي'!$C:$C,$A3,'محمد عرابي'!$F:$F,"<>")-SUMIFS('محمد عرابي'!$D:$D,'محمد عرابي'!$C:$C,$A3,'محمد عرابي'!$G:$G,"<>",'محمد عرابي'!$F:$F,"")) -> 0 | U3: =IF($A3="","",SUMIFS('عم جمال'!$D:$D,'عم جمال'!$C:$C,$A3,'عم جمال'!$F:$F,"<>")-SUMIFS('عم جمال'!$D:$D,'عم جمال'!$C:$C,$A3,'عم جمال'!$G:$G,"<>",'عم جمال'!$F:$F,"")) -> 16 | V3: =IF($A3="","",SUMIFS('فاير سيليكت'!$D:$D,'فاير سيليكت'!$C:$C,$A3,'فاير سيليكت'!$F:$F,"<>")-SUMIFS('فاير سيليكت'!$D:$D,'فاير سيليكت'!$C:$C,$A3,'فاير سيليكت'!$G:$G,"<>",'فاير سيليكت'!$F:$F,"")) -> 0 | W3: =IF($A3="","",SUMIFS(فرانكو!$D:$D,فرانكو!$C:$C,$A3,فرانكو!$F:$F,"<>")-SUMIFS(فرانكو!$D:$D,فرانكو!$C:$C,$A3,فرانكو!$G:$G,"<>",فرانكو!$F:$F,"")) -> 0 | X3: =IF($A3="","",SUMIFS('كريم بكر'!$D:$D,'كريم بكر'!$C:$C,$A3,'كريم بكر'!$F:$F,"<>")-SUMIFS('كريم بكر'!$D:$D,'كريم بكر'!$C:$C,$A3,'كريم بكر'!$G:$G,"<>",'كريم بكر'!$F:$F,"")) -> 0 | Y3: =IF($A3="","",SUMIFS(بفرا!$D:$D,بفرا!$C:$C,$A3,بفرا!$F:$F,"<>")-SUMIFS(بفرا!$D:$D,بفرا!$C:$C,$A3,بفرا!$G:$G,"<>",بفرا!$F:$F,"")) -> 0 | Z3: =IF($A3="","",SUMIFS('محل كوم النور'!$D:$D,'محل كوم النور'!$C:$C,$A3,'محل كوم النور'!$F:$F,"<>")-SUMIFS('محل كوم النور'!$D:$D,'محل كوم النور'!$C:$C,$A3,'محل كوم النور'!$G:$G,"<>",'محل كوم النور'!$F:$F,"")) -> 12 | AA3: =IF($A3="","",SUMIFS('محمد النجار'!$D:$D,'محمد النجار'!$C:$C,$A3,'محمد النجار'!$F:$F,"<>")-SUMIFS('محمد النجار'!$D:$D,'محمد النجار'!$C:$C,$A3,'محمد النجار'!$G:$G,"<>",'محمد النجار'!$F:$F,"")) -> 0 | AB3: =IF($A3="","",SUMIFS('محمود عبدالرسول'!$D:$D,'محمود عبدالرسول'!$C:$C,$A3,'محمود عبدالرسول'!$F:$F,"<>")-SUMIFS('محمود عبدالرسول'!$D:$D,'محمود عبدالرسول'!$C:$C,$A3,'محمود عبدالرسول'!$G:$G,"<>",'محمود عبدالرسول'!$F:$F,"")) -> 0 | AC3: =IF($A3="","",SUMIFS('مول المصطفي'!$D:$D,'مول المصطفي'!$C:$C,$A3,'مول المصطفي'!$F:$F,"<>")-SUMIFS('مول المصطفي'!$D:$D,'مول المصطفي'!$C:$C,$A3,'مول المصطفي'!$G:$G,"<>",'مول المصطفي'!$F:$F,"")) -> 24 | AD3: =IF($A3="","",SUMIFS(مصانع!$D:$D,مصانع!$C:$C,$A3,مصانع!$F:$F,"<>")-SUMIFS(مصانع!$D:$D,مصانع!$C:$C,$A3,مصانع!$G:$G,"<>",مصانع!$F:$F,"")) -> 0 | AE3: =IF($A3="","",SUM(B3:AD3)) -> 131 | AF3: شروال سمر ميلتون جوردن | AG3: 160 | AH3: =IF(OR($A3="",AG3=""),"",AG3-AE3) -> 29 | AI3: 325 | AJ3: =IF(OR($A3="",AH3=""),"",AH3*AI3) -> 9425
A4: B02 | B4: =IF($A4="","",SUMIFS('4K حموده'!$D:$D,'4K حموده'!$C:$C,$A4,'4K حموده'!$F:$F,"<>")-SUMIFS('4K حموده'!$D:$D,'4K حموده'!$C:$C,$A4,'4K حموده'!$G:$G,"<>",'4K حموده'!$F:$F,"")) -> 0 | C4: =IF($A4="","",SUMIFS('مكتب القاضي'!$D:$D,'مكتب القاضي'!$C:$C,$A4,'مكتب القاضي'!$F:$F,"<>")-SUMIFS('مكتب القاضي'!$D:$D,'مكتب القاضي'!$C:$C,$A4,'مكتب القاضي'!$G:$G,"<>",'مكتب القاضي'!$F:$F,"")) -> 5 | D4: =IF($A4="","",SUMIFS(الاتشو!$D:$D,الاتشو!$C:$C,$A4,الاتشو!$F:$F,"<>")-SUMIFS(الاتشو!$D:$D,الاتشو!$C:$C,$A4,الاتشو!$G:$G,"<>",الاتشو!$F:$F,"")) -> 0 | E4: =IF($A4="","",SUMIFS('علاء بوم ارض النت'!$D:$D,'علاء بوم ارض النت'!$C:$C,$A4,'علاء بوم ارض النت'!$F:$F,"<>")-SUMIFS('علاء بوم ارض النت'!$D:$D,'علاء بوم ارض النت'!$C:$C,$A4,'علاء بوم ارض النت'!$G:$G,"<>",'علاء بوم ارض النت'!$F:$F,"")) -> 16 | F4: =IF($A4="","",SUMIFS('كيمو ميت ابو خالد'!$D:$D,'كيمو ميت ابو خالد'!$C:$C,$A4,'كيمو ميت ابو خالد'!$F:$F,"<>")-SUMIFS('كيمو ميت ابو خالد'!$D:$D,'كيمو ميت ابو خالد'!$C:$C,$A4,'كيمو ميت ابو خالد'!$G:$G,"<>",'كيمو ميت ابو خالد'!$F:$F,"")) -> 0 | G4: =IF($A4="","",SUMIFS(KAZO!$D:$D,KAZO!$C:$C,$A4,KAZO!$F:$F,"<>")-SUMIFS(KAZO!$D:$D,KAZO!$C:$C,$A4,KAZO!$G:$G,"<>",KAZO!$F:$F,"")) -> 8 | H4: =IF($A4="","",SUMIFS(LAFY!$D:$D,LAFY!$C:$C,$A4,LAFY!$F:$F,"<>")-SUMIFS(LAFY!$D:$D,LAFY!$C:$C,$A4,LAFY!$G:$G,"<>",LAFY!$F:$F,"")) -> 0 | I4: =IF($A4="","",SUMIFS('POINT زفتي (جديد)'!$D:$D,'POINT زفتي (جديد)'!$C:$C,$A4,'POINT زفتي (جديد)'!$F:$F,"<>")-SUMIFS('POINT زفتي (جديد)'!$D:$D,'POINT زفتي (جديد)'!$C:$C,$A4,'POINT زفتي (جديد)'!$G:$G,"<>",'POINT زفتي (جديد)'!$F:$F,"")) -> 18 | J4: =IF($A4="","",SUMIFS('POINT سعد زغلول (قديم)'!$D:$D,'POINT سعد زغلول (قديم)'!$C:$C,$A4,'POINT سعد زغلول (قديم)'!$F:$F,"<>")-SUMIFS('POINT سعد زغلول (قديم)'!$D:$D,'POINT سعد زغلول (قديم)'!$C:$C,$A4,'POINT سعد زغلول (قديم)'!$G:$G,"<>",'POINT سعد زغلول (قديم)'!$F:$F,"")) -> 0 | K4: =IF($A4="","",SUMIFS('POWER ارض النت'!$D:$D,'POWER ارض النت'!$C:$C,$A4,'POWER ارض النت'!$F:$F,"<>")-SUMIFS('POWER ارض النت'!$D:$D,'POWER ارض النت'!$C:$C,$A4,'POWER ارض النت'!$G:$G,"<>",'POWER ارض النت'!$F:$F,"")) -> 0 | L4: =IF($A4="","",SUMIFS('POWER زفتي'!$D:$D,'POWER زفتي'!$C:$C,$A4,'POWER زفتي'!$F:$F,"<>")-SUMIFS('POWER زفتي'!$D:$D,'POWER زفتي'!$C:$C,$A4,'POWER زفتي'!$G:$G,"<>",'POWER زفتي'!$F:$F,"")) -> 8 | M4: =IF($A4="","",SUMIFS('احمد المنوفي'!$D:$D,'احمد المنوفي'!$C:$C,$A4,'احمد المنوفي'!$F:$F,"<>")-SUMIFS('احمد المنوفي'!$D:$D,'احمد المنوفي'!$C:$C,$A4,'احمد المنوفي'!$G:$G,"<>",'احمد المنوفي'!$F:$F,"")) -> 0 | N4: =IF($A4="","",SUMIFS(السفير!$D:$D,السفير!$C:$C,$A4,السفير!$F:$F,"<>")-SUMIFS(السفير!$D:$D,السفير!$C:$C,$A4,السفير!$G:$G,"<>",السفير!$F:$F,"")) -> 16 | O4: =IF($A4="","",SUMIFS(العالمي!$D:$D,العالمي!$C:$C,$A4,العالمي!$F:$F,"<>")-SUMIFS(العالمي!$D:$D,العالمي!$C:$C,$A4,العالمي!$G:$G,"<>",العالمي!$F:$F,"")) -> 0 | P4: =IF($A4="","",SUMIFS('باهي التركي'!$D:$D,'باهي التركي'!$C:$C,$A4,'باهي التركي'!$F:$F,"<>")-SUMIFS('باهي التركي'!$D:$D,'باهي التركي'!$C:$C,$A4,'باهي التركي'!$G:$G,"<>",'باهي التركي'!$F:$F,"")) -> 0 | Q4: =IF($A4="","",SUMIFS('توتي دماص'!$D:$D,'توتي دماص'!$C:$C,$A4,'توتي دماص'!$F:$F,"<>")-SUMIFS('توتي دماص'!$D:$D,'توتي دماص'!$C:$C,$A4,'توتي دماص'!$G:$G,"<>",'توتي دماص'!$F:$F,"")) -> 0 | R4: =IF($A4="","",SUMIFS('رضا محمد'!$D:$D,'رضا محمد'!$C:$C,$A4,'رضا محمد'!$F:$F,"<>")-SUMIFS('رضا محمد'!$D:$D,'رضا محمد'!$C:$C,$A4,'رضا محمد'!$G:$G,"<>",'رضا محمد'!$F:$F,"")) -> 8 | S4: =IF($A4="","",SUMIFS('زومبي العشري'!$D:$D,'زومبي العشري'!$C:$C,$A4,'زومبي العشري'!$F:$F,"<>")-SUMIFS('زومبي العشري'!$D:$D,'زومبي العشري'!$C:$C,$A4,'زومبي العشري'!$G:$G,"<>",'زومبي العشري'!$F:$F,"")) -> 0 | T4: =IF($A4="","",SUMIFS('محمد عرابي'!$D:$D,'محمد عرابي'!$C:$C,$A4,'محمد عرابي'!$F:$F,"<>")-SUMIFS('محمد عرابي'!$D:$D,'محمد عرابي'!$C:$C,$A4,'محمد عرابي'!$G:$G,"<>",'محمد عرابي'!$F:$F,"")) -> 0 | U4: =IF($A4="","",SUMIFS('عم جمال'!$D:$D,'عم جمال'!$C:$C,$A4,'عم جمال'!$F:$F,"<>")-SUMIFS('عم جمال'!$D:$D,'عم جمال'!$C:$C,$A4,'عم جمال'!$G:$G,"<>",'عم جمال'!$F:$F,"")) -> 0 | V4: =IF($A4="","",SUMIFS('فاير سيليكت'!$D:$D,'فاير سيليكت'!$C:$C,$A4,'فاير سيليكت'!$F:$F,"<>")-SUMIFS('فاير سيليكت'!$D:$D,'فاير سيليكت'!$C:$C,$A4,'فاير سيليكت'!$G:$G,"<>",'فاير سيليكت'!$F:$F,"")) -> 0 | W4: =IF($A4="","",SUMIFS(فرانكو!$D:$D,فرانكو!$C:$C,$A4,فرانكو!$F:$F,"<>")-SUMIFS(فرانكو!$D:$D,فرانكو!$C:$C,$A4,فرانكو!$G:$G,"<>",فرانكو!$F:$F,"")) -> 0 | X4: =IF($A4="","",SUMIFS('كريم بكر'!$D:$D,'كريم بكر'!$C:$C,$A4,'كريم بكر'!$F:$F,"<>")-SUMIFS('كريم بكر'!$D:$D,'كريم بكر'!$C:$C,$A4,'كريم بكر'!$G:$G,"<>",'كريم بكر'!$F:$F,"")) -> 0 | Y4: =IF($A4="","",SUMIFS(بفرا!$D:$D,بفرا!$C:$C,$A4,بفرا!$F:$F,"<>")-SUMIFS(بفرا!$D:$D,بفرا!$C:$C,$A4,بفرا!$G:$G,"<>",بفرا!$F:$F,"")) -> 0 | Z4: =IF($A4="","",SUMIFS('محل كوم النور'!$D:$D,'محل كوم النور'!$C:$C,$A4,'محل كوم النور'!$F:$F,"<>")-SUMIFS('محل كوم النور'!$D:$D,'محل كوم النور'!$C:$C,$A4,'محل كوم النور'!$G:$G,"<>",'محل كوم النور'!$F:$F,"")) -> 4 | AA4: =IF($A4="","",SUMIFS('محمد النجار'!$D:$D,'محمد النجار'!$C:$C,$A4,'محمد النجار'!$F:$F,"<>")-SUMIFS('محمد النجار'!$D:$D,'محمد النجار'!$C:$C,$A4,'محمد النجار'!$G:$G,"<>",'محمد النجار'!$F:$F,"")) -> 0 | AB4: =IF($A4="","",SUMIFS('محمود عبدالرسول'!$D:$D,'محمود عبدالرسول'!$C:$C,$A4,'محمود عبدالرسول'!$F:$F,"<>")-SUMIFS('محمود عبدالرسول'!$D:$D,'محمود عبدالرسول'!$C:$C,$A4,'محمود عبدالرسول'!$G:$G,"<>",'محمود عبدالرسول'!$F:$F,"")) -> 8 | AC4: =IF($A4="","",SUMIFS('مول المصطفي'!$D:$D,'مول المصطفي'!$C:$C,$A4,'مول المصطفي'!$F:$F,"<>")-SUMIFS('مول المصطفي'!$D:$D,'مول المصطفي'!$C:$C,$A4,'مول المصطفي'!$G:$G,"<>",'مول المصطفي'!$F:$F,"")) -> 0 | AD4: =IF($A4="","",SUMIFS(مصانع!$D:$D,مصانع!$C:$C,$A4,مصانع!$F:$F,"<>")-SUMIFS(مصانع!$D:$D,مصانع!$C:$C,$A4,مصانع!$G:$G,"<>",مصانع!$F:$F,"")) -> 0 | AE4: =IF($A4="","",SUM(B4:AD4)) -> 91 | AF4: شروال وايد ليج بالنسياجا انتر لوك | AG4: 116 | AH4: =IF(OR($A4="",AG4=""),"",AG4-AE4) -> 25 | AI4: 370 | AJ4: =IF(OR($A4="",AH4=""),"",AH4*AI4) -> 9250
A5: B03 | B5: =IF($A5="","",SUMIFS('4K حموده'!$D:$D,'4K حموده'!$C:$C,$A5,'4K حموده'!$F:$F,"<>")-SUMIFS('4K حموده'!$D:$D,'4K حموده'!$C:$C,$A5,'4K حموده'!$G:$G,"<>",'4K حموده'!$F:$F,"")) -> 0 | C5: =IF($A5="","",SUMIFS('مكتب القاضي'!$D:$D,'مكتب القاضي'!$C:$C,$A5,'مكتب القاضي'!$F:$F,"<>")-SUMIFS('مكتب القاضي'!$D:$D,'مكتب القاضي'!$C:$C,$A5,'مكتب القاضي'!$G:$G,"<>",'مكتب القاضي'!$F:$F,"")) -> 16 | D5: =IF($A5="","",SUMIFS(الاتشو!$D:$D,الاتشو!$C:$C,$A5,الاتشو!$F:$F,"<>")-SUMIFS(الاتشو!$D:$D,الاتشو!$C:$C,$A5,الاتشو!$G:$G,"<>",الاتشو!$F:$F,"")) -> 0 | E5: =IF($A5="","",SUMIFS('علاء بوم ارض النت'!$D:$D,'علاء بوم ارض النت'!$C:$C,$A5,'علاء بوم ارض النت'!$F:$F,"<>")-SUMIFS('علاء بوم ارض النت'!$D:$D,'علاء بوم ارض النت'!$C:$C,$A5,'علاء بوم ارض النت'!$G:$G,"<>",'علاء بوم ارض النت'!$F:$F,"")) -> 20 | F5: =IF($A5="","",SUMIFS('كيمو ميت ابو خالد'!$D:$D,'كيمو ميت ابو خالد'!$C:$C,$A5,'كيمو ميت ابو خالد'!$F:$F,"<>")-SUMIFS('كيمو ميت ابو خالد'!$D:$D,'كيمو ميت ابو خالد'!$C:$C,$A5,'كيمو ميت ابو خالد'!$G:$G,"<>",'كيمو ميت ابو خالد'!$F:$F,"")) -> 0 | G5: =IF($A5="","",SUMIFS(KAZO!$D:$D,KAZO!$C:$C,$A5,KAZO!$F:$F,"<>")-SUMIFS(KAZO!$D:$D,KAZO!$C:$C,$A5,KAZO!$G:$G,"<>",KAZO!$F:$F,"")) -> 8 | H5: =IF($A5="","",SUMIFS(LAFY!$D:$D,LAFY!$C:$C,$A5,LAFY!$F:$F,"<>")-SUMIFS(LAFY!$D:$D,LAFY!$C:$C,$A5,LAFY!$G:$G,"<>",LAFY!$F:$F,"")) -> 0 | I5: =IF($A5="","",SUMIFS('POINT زفتي (جديد)'!$D:$D,'POINT زفتي (جديد)'!$C:$C,$A5,'POINT زفتي (جديد)'!$F:$F,"<>")-SUMIFS('POINT زفتي (جديد)'!$D:$D,'POINT زفتي (جديد)'!$C:$C,$A5,'POINT زفتي (جديد)'!$G:$G,"<>",'POINT زفتي (جديد)'!$F:$F,"")) -> 0 | J5: =IF($A5="","",SUMIFS('POINT سعد زغلول (قديم)'!$D:$D,'POINT سعد زغلول (قديم)'!$C:$C,$A5,'POINT سعد زغلول (قديم)'!$F:$F,"<>")-SUMIFS('POINT سعد زغلول (قديم)'!$D:$D,'POINT سعد زغلول (قديم)'!$C:$C,$A5,'POINT سعد زغلول (قديم)'!$G:$G,"<>",'POINT سعد زغلول (قديم)'!$F:$F,"")) -> 0 | K5: =IF($A5="","",SUMIFS('POWER ارض النت'!$D:$D,'POWER ارض النت'!$C:$C,$A5,'POWER ارض النت'!$F:$F,"<>")-SUMIFS('POWER ارض النت'!$D:$D,'POWER ارض النت'!$C:$C,$A5,'POWER ارض النت'!$G:$G,"<>",'POWER ارض النت'!$F:$F,"")) -> 0 | L5: =IF($A5="","",SUMIFS('POWER زفتي'!$D:$D,'POWER زفتي'!$C:$C,$A5,'POWER زفتي'!$F:$F,"<>")-SUMIFS('POWER زفتي'!$D:$D,'POWER زفتي'!$C:$C,$A5,'POWER زفتي'!$G:$G,"<>",'POWER زفتي'!$F:$F,"")) -> 0 | M5: =IF($A5="","",SUMIFS('احمد المنوفي'!$D:$D,'احمد المنوفي'!$C:$C,$A5,'احمد المنوفي'!$F:$F,"<>")-SUMIFS('احمد المنوفي'!$D:$D,'احمد المنوفي'!$C:$C,$A5,'احمد المنوفي'!$G:$G,"<>",'احمد المنوفي'!$F:$F,"")) -> 0 | N5: =IF($A5="","",SUMIFS(السفير!$D:$D,السفير!$C:$C,$A5,السفير!$F:$F,"<>")-SUMIFS(السفير!$D:$D,السفير!$C:$C,$A5,السفير!$G:$G,"<>",السفير!$F:$F,"")) -> 0 | O5: =IF($A5="","",SUMIFS(العالمي!$D:$D,العالمي!$C:$C,$A5,العالمي!$F:$F,"<>")-SUMIFS(العالمي!$D:$D,العالمي!$C:$C,$A5,العالمي!$G:$G,"<>",العالمي!$F:$F,"")) -> 0 | P5: =IF($A5="","",SUMIFS('باهي التركي'!$D:$D,'باهي التركي'!$C:$C,$A5,'باهي التركي'!$F:$F,"<>")-SUMIFS('باهي التركي'!$D:$D,'باهي التركي'!$C:$C,$A5,'باهي التركي'!$G:$G,"<>",'باهي التركي'!$F:$F,"")) -> 16 | Q5: =IF($A5="","",SUMIFS('توتي دماص'!$D:$D,'توتي دماص'!$C:$C,$A5,'توتي دماص'!$F:$F,"<>")-SUMIFS('توتي دماص'!$D:$D,'توتي دماص'!$C:$C,$A5,'توتي دماص'!$G:$G,"<>",'توتي دماص'!$F:$F,"")) -> 0 | R5: =IF($A5="","",SUMIFS('رضا محمد'!$D:$D,'رضا محمد'!$C:$C,$A5,'رضا محمد'!$F:$F,"<>")-SUMIFS('رضا محمد'!$D:$D,'رضا محمد'!$C:$C,$A5,'رضا محمد'!$G:$G,"<>",'رضا محمد'!$F:$F,"")) -> 0 | S5: =IF($A5="","",SUMIFS('زومبي العشري'!$D:$D,'زومبي العشري'!$C:$C,$A5,'زومبي العشري'!$F:$F,"<>")-SUMIFS('زومبي العشري'!$D:$D,'زومبي العشري'!$C:$C,$A5,'زومبي العشري'!$G:$G,"<>",'زومبي العشري'!$F:$F,"")) -> 0 | T5: =IF($A5="","",SUMIFS('محمد عرابي'!$D:$D,'محمد عرابي'!$C:$C,$A5,'محمد عرابي'!$F:$F,"<>")-SUMIFS('محمد عرابي'!$D:$D,'محمد عرابي'!$C:$C,$A5,'محمد عرابي'!$G:$G,"<>",'محمد عرابي'!$F:$F,"")) -> 0 | U5: =IF($A5="","",SUMIFS('عم جمال'!$D:$D,'عم جمال'!$C:$C,$A5,'عم جمال'!$F:$F,"<>")-SUMIFS('عم جمال'!$D:$D,'عم جمال'!$C:$C,$A5,'عم جمال'!$G:$G,"<>",'عم جمال'!$F:$F,"")) -> 0 | V5: =IF($A5="","",SUMIFS('فاير سيليكت'!$D:$D,'فاير سيليكت'!$C:$C,$A5,'فاير سيليكت'!$F:$F,"<>")-SUMIFS('فاير سيليكت'!$D:$D,'فاير سيليكت'!$C:$C,$A5,'فاير سيليكت'!$G:$G,"<>",'فاير سيليكت'!$F:$F,"")) -> 0 | W5: =IF($A5="","",SUMIFS(فرانكو!$D:$D,فرانكو!$C:$C,$A5,فرانكو!$F:$F,"<>")-SUMIFS(فرانكو!$D:$D,فرانكو!$C:$C,$A5,فرانكو!$G:$G,"<>",فرانكو!$F:$F,"")) -> 0 | X5: =IF($A5="","",SUMIFS('كريم بكر'!$D:$D,'كريم بكر'!$C:$C,$A5,'كريم بكر'!$F:$F,"<>")-SUMIFS('كريم بكر'!$D:$D,'كريم بكر'!$C:$C,$A5,'كريم بكر'!$G:$G,"<>",'كريم بكر'!$F:$F,"")) -> 0 | Y5: =IF($A5="","",SUMIFS(بفرا!$D:$D,بفرا!$C:$C,$A5,بفرا!$F:$F,"<>")-SUMIFS(بفرا!$D:$D,بفرا!$C:$C,$A5,بفرا!$G:$G,"<>",بفرا!$F:$F,"")) -> 0 | Z5: =IF($A5="","",SUMIFS('محل كوم النور'!$D:$D,'محل كوم النور'!$C:$C,$A5,'محل كوم النور'!$F:$F,"<>")-SUMIFS('محل كوم النور'!$D:$D,'محل كوم النور'!$C:$C,$A5,'محل كوم النور'!$G:$G,"<>",'محل كوم النور'!$F:$F,"")) -> 0 | AA5: =IF($A5="","",SUMIFS('محمد النجار'!$D:$D,'محمد النجار'!$C:$C,$A5,'محمد النجار'!$F:$F,"<>")-SUMIFS('محمد النجار'!$D:$D,'محمد النجار'!$C:$C,$A5,'محمد النجار'!$G:$G,"<>",'محمد النجار'!$F:$F,"")) -> 0 | AB5: =IF($A5="","",SUMIFS('محمود عبدالرسول'!$D:$D,'محمود عبدالرسول'!$C:$C,$A5,'محمود عبدالرسول'!$F:$F,"<>")-SUMIFS('محمود عبدالرسول'!$D:$D,'محمود عبدالرسول'!$C:$C,$A5,'محمود عبدالرسول'!$G:$G,"<>",'محمود عبدالرسول'!$F:$F,"")) -> 8 | AC5: =IF($A5="","",SUMIFS('مول المصطفي'!$D:$D,'مول المصطفي'!$C:$C,$A5,'مول المصطفي'!$F:$F,"<>")-SUMIFS('مول المصطفي'!$D:$D,'مول المصطفي'!$C:$C,$A5,'مول المصطفي'!$G:$G,"<>",'مول المصطفي'!$F:$F,"")) -> 0 | AD5: =IF($A5="","",SUMIFS(مصانع!$D:$D,مصانع!$C:$C,$A5,مصانع!$F:$F,"<>")-SUMIFS(مصانع!$D:$D,مصانع!$C:$C,$A5,مصانع!$G:$G,"<>",مصانع!$F:$F,"")) -> 0 | AE5: =IF($A5="","",SUM(B5:AD5)) -> 68 | AF5: شروال سمر ميلتون اوفر سايز | AG5: 138 | AH5: =IF(OR($A5="",AG5=""),"",AG5-AE5) -> 70 | AI5: 310 | AJ5: =IF(OR($A5="",AH5=""),"",AH5*AI5) -> 21700
A6: B04 | B6: =IF($A6="","",SUMIFS('4K حموده'!$D:$D,'4K حموده'!$C:$C,$A6,'4K حموده'!$F:$F,"<>")-SUMIFS('4K حموده'!$D:$D,'4K حموده'!$C:$C,$A6,'4K حموده'!$G:$G,"<>",'4K حموده'!$F:$F,"")) -> 0 | C6: =IF($A6="","",SUMIFS('مكتب القاضي'!$D:$D,'مكتب القاضي'!$C:$C,$A6,'مكتب القاضي'!$F:$F,"<>")-SUMIFS('مكتب القاضي'!$D:$D,'مكتب القاضي'!$C:$C,$A6,'مكتب القاضي'!$G:$G,"<>",'مكتب القاضي'!$F:$F,"")) -> 8 | D6: =IF($A6="","",SUMIFS(الاتشو!$D:$D,الاتشو!$C:$C,$A6,الاتشو!$F:$F,"<>")-SUMIFS(الاتشو!$D:$D,الاتشو!$C:$C,$A6,الاتشو!$G:$G,"<>",الاتشو!$F:$F,"")) -> 0 | E6: =IF($A6="","",SUMIFS('علاء بوم ارض النت'!$D:$D,'علاء بوم ارض النت'!$C:$C,$A6,'علاء بوم ارض النت'!$F:$F,"<>")-SUMIFS('علاء بوم ارض النت'!$D:$D,'علاء بوم ارض النت'!$C:$C,$A6,'علاء بوم ارض النت'!$G:$G,"<>",'علاء بوم ارض النت'!$F:$F,"")) -> 59 | F6: =IF($A6="","",SUMIFS('كيمو ميت ابو خالد'!$D:$D,'كيمو ميت ابو خالد'!$C:$C,$A6,'كيمو ميت ابو خالد'!$F:$F,"<>")-SUMIFS('كيمو ميت ابو خالد'!$D:$D,'كيمو ميت ابو خالد'!$C:$C,$A6,'كيمو ميت ابو خالد'!$G:$G,"<>",'كيمو ميت ابو خالد'!$F:$F,"")) -> 0 | G6: =IF($A6="","",SUMIFS(KAZO!$D:$D,KAZO!$C:$C,$A6,KAZO!$F:$F,"<>")-SUMIFS(KAZO!$D:$D,KAZO!$C:$C,$A6,KAZO!$G:$G,"<>",KAZO!$F:$F,"")) -> 0 | H6: =IF($A6="","",SUMIFS(LAFY!$D:$D,LAFY!$C:$C,$A6,LAFY!$F:$F,"<>")-SUMIFS(LAFY!$D:$D,LAFY!$C:$C,$A6,LAFY!$G:$G,"<>",LAFY!$F:$F,"")) -> 0 | I6: =IF($A6="","",SUMIFS('POINT زفتي (جديد)'!$D:$D,'POINT زفتي (جديد)'!$C:$C,$A6,'POINT زفتي (جديد)'!$F:$F,"<>")-SUMIFS('POINT زفتي (جديد)'!$D:$D,'POINT زفتي (جديد)'!$C:$C,$A6,'POINT زفتي (جديد)'!$G:$G,"<>",'POINT زفتي (جديد)'!$F:$F,"")) -> 12 | J6: =IF($A6="","",SUMIFS('POINT سعد زغلول (قديم)'!$D:$D,'POINT سعد زغلول (قديم)'!$C:$C,$A6,'POINT سعد زغلول (قديم)'!$F:$F,"<>")-SUMIFS('POINT سعد زغلول (قديم)'!$D:$D,'POINT سعد زغلول (قديم)'!$C:$C,$A6,'POINT سعد زغلول (قديم)'!$G:$G,"<>",'POINT سعد زغلول (قديم)'!$F:$F,"")) -> 0 | K6: =IF($A6="","",SUMIFS('POWER ارض النت'!$D:$D,'POWER ارض النت'!$C:$C,$A6,'POWER ارض النت'!$F:$F,"<>")-SUMIFS('POWER ارض النت'!$D:$D,'POWER ارض النت'!$C:$C,$A6,'POWER ارض النت'!$G:$G,"<>",'POWER ارض النت'!$F:$F,"")) -> 0 | L6: =IF($A6="","",SUMIFS('POWER زفتي'!$D:$D,'POWER زفتي'!$C:$C,$A6,'POWER زفتي'!$F:$F,"<>")-SUMIFS('POWER زفتي'!$D:$D,'POWER زفتي'!$C:$C,$A6,'POWER زفتي'!$G:$G,"<>",'POWER زفتي'!$F:$F,"")) -> 12 | M6: =IF($A6="","",SUMIFS('احمد المنوفي'!$D:$D,'احمد المنوفي'!$C:$C,$A6,'احمد المنوفي'!$F:$F,"<>")-SUMIFS('احمد المنوفي'!$D:$D,'احمد المنوفي'!$C:$C,$A6,'احمد المنوفي'!$G:$G,"<>",'احمد المنوفي'!$F:$F,"")) -> 0 | N6: =IF($A6="","",SUMIFS(السفير!$D:$D,السفير!$C:$C,$A6,السفير!$F:$F,"<>")-SUMIFS(السفير!$D:$D,السفير!$C:$C,$A6,السفير!$G:$G,"<>",السفير!$F:$F,"")) -> 12 | O6: =IF($A6="","",SUMIFS(العالمي!$D:$D,العالمي!$C:$C,$A6,العالمي!$F:$F,"<>")-SUMIFS(العالمي!$D:$D,العالمي!$C:$C,$A6,العالمي!$G:$G,"<>",العالمي!$F:$F,"")) -> 0 | P6: =IF($A6="","",SUMIFS('باهي التركي'!$D:$D,'باهي التركي'!$C:$C,$A6,'باهي التركي'!$F:$F,"<>")-SUMIFS('باهي التركي'!$D:$D,'باهي التركي'!$C:$C,$A6,'باهي التركي'!$G:$G,"<>",'باهي التركي'!$F:$F,"")) -> 40 | Q6: =IF($A6="","",SUMIFS('توتي دماص'!$D:$D,'توتي دماص'!$C:$C,$A6,'توتي دماص'!$F:$F,"<>")-SUMIFS('توتي دماص'!$D:$D,'توتي دماص'!$C:$C,$A6,'توتي دماص'!$G:$G,"<>",'توتي دماص'!$F:$F,"")) -> 0 | R6: =IF($A6="","",SUMIFS('رضا محمد'!$D:$D,'رضا محمد'!$C:$C,$A6,'رضا محمد'!$F:$F,"<>")-SUMIFS('رضا محمد'!$D:$D,'رضا محمد'!$C:$C,$A6,'رضا محمد'!$G:$G,"<>",'رضا محمد'!$F:$F,"")) -> 3 | S6: =IF($A6="","",SUMIFS('زومبي العشري'!$D:$D,'زومبي العشري'!$C:$C,$A6,'زومبي العشري'!$F:$F,"<>")-SUMIFS('زومبي العشري'!$D:$D,'زومبي العشري'!$C:$C,$A6,'زومبي العشري'!$G:$G,"<>",'زومبي العشري'!$F:$F,"")) -> 0 | T6: =IF($A6="","",SUMIFS('محمد عرابي'!$D:$D,'محمد عرابي'!$C:$C,$A6,'محمد عرابي'!$F:$F,"<>")-SUMIFS('محمد عرابي'!$D:$D,'محمد عرابي'!$C:$C,$A6,'محمد عرابي'!$G:$G,"<>",'محمد عرابي'!$F:$F,"")) -> 0 | U6: =IF($A6="","",SUMIFS('عم جمال'!$D:$D,'عم جمال'!$C:$C,$A6,'عم جمال'!$F:$F,"<>")-SUMIFS('عم جمال'!$D:$D,'عم جمال'!$C:$C,$A6,'عم جمال'!$G:$G,"<>",'عم جمال'!$F:$F,"")) -> 0 | V6: =IF($A6="","",SUMIFS('فاير سيليكت'!$D:$D,'فاير سيليكت'!$C:$C,$A6,'فاير سيليكت'!$F:$F,"<>")-SUMIFS('فاير سيليكت'!$D:$D,'فاير سيليكت'!$C:$C,$A6,'فاير سيليكت'!$G:$G,"<>",'فاير سيليكت'!$F:$F,"")) -> 0 | W6: =IF($A6="","",SUMIFS(فرانكو!$D:$D,فرانكو!$C:$C,$A6,فرانكو!$F:$F,"<>")-SUMIFS(فرانكو!$D:$D,فرانكو!$C:$C,$A6,فرانكو!$G:$G,"<>",فرانكو!$F:$F,"")) -> 0 | X6: =IF($A6="","",SUMIFS('كريم بكر'!$D:$D,'كريم بكر'!$C:$C,$A6,'كريم بكر'!$F:$F,"<>")-SUMIFS('كريم بكر'!$D:$D,'كريم بكر'!$C:$C,$A6,'كريم بكر'!$G:$G,"<>",'كريم بكر'!$F:$F,"")) -> 0 | Y6: =IF($A6="","",SUMIFS(بفرا!$D:$D,بفرا!$C:$C,$A6,بفرا!$F:$F,"<>")-SUMIFS(بفرا!$D:$D,بفرا!$C:$C,$A6,بفرا!$G:$G,"<>",بفرا!$F:$F,"")) -> 0 | Z6: =IF($A6="","",SUMIFS('محل كوم النور'!$D:$D,'محل كوم النور'!$C:$C,$A6,'محل كوم النور'!$F:$F,"<>")-SUMIFS('محل كوم النور'!$D:$D,'محل كوم النور'!$C:$C,$A6,'محل كوم النور'!$G:$G,"<>",'محل كوم النور'!$F:$F,"")) -> 6 | AA6: =IF($A6="","",SUMIFS('محمد النجار'!$D:$D,'محمد النجار'!$C:$C,$A6,'محمد النجار'!$F:$F,"<>")-SUMIFS('محمد النجار'!$D:$D,'محمد النجار'!$C:$C,$A6,'محمد النجار'!$G:$G,"<>",'محمد النجار'!$F:$F,"")) -> 0 | AB6: =IF($A6="","",SUMIFS('محمود عبدالرسول'!$D:$D,'محمود عبدالرسول'!$C:$C,$A6,'محمود عبدالرسول'!$F:$F,"<>")-SUMIFS('محمود عبدالرسول'!$D:$D,'محمود عبدالرسول'!$C:$C,$A6,'محمود عبدالرسول'!$G:$G,"<>",'محمود عبدالرسول'!$F:$F,"")) -> 20 | AC6: =IF($A6="","",SUMIFS('مول المصطفي'!$D:$D,'مول المصطفي'!$C:$C,$A6,'مول المصطفي'!$F:$F,"<>")-SUMIFS('مول المصطفي'!$D:$D,'مول المصطفي'!$C:$C,$A6,'مول المصطفي'!$G:$G,"<>",'مول المصطفي'!$F:$F,"")) -> 16 | AD6: =IF($A6="","",SUMIFS(مصانع!$D:$D,مصانع!$C:$C,$A6,مصانع!$F:$F,"<>")-SUMIFS(مصانع!$D:$D,مصانع!$C:$C,$A6,مصانع!$G:$G,"<>",مصانع!$F:$F,"")) -> 1 | AE6: =IF($A6="","",SUM(B6:AD6)) -> 189 | AF6: شروال باجي انتر لوك | AG6: 219 | AH6: =IF(OR($A6="",AG6=""),"",AG6-AE6) -> 30 | AI6: 420 | AJ6: =IF(OR($A6="",AH6=""),"",AH6*AI6) -> 12600
A7: B101 | B7: =IF($A7="","",SUMIFS('4K حموده'!$D:$D,'4K حموده'!$C:$C,$A7,'4K حموده'!$F:$F,"<>")-SUMIFS('4K حموده'!$D:$D,'4K حموده'!$C:$C,$A7,'4K حموده'!$G:$G,"<>",'4K حموده'!$F:$F,"")) -> 0 | C7: =IF($A7="","",SUMIFS('مكتب القاضي'!$D:$D,'مكتب القاضي'!$C:$C,$A7,'مكتب القاضي'!$F:$F,"<>")-SUMIFS('مكتب القاضي'!$D:$D,'مكتب القاضي'!$C:$C,$A7,'مكتب القاضي'!$G:$G,"<>",'مكتب القاضي'!$F:$F,"")) -> 0 | D7: =IF($A7="","",SUMIFS(الاتشو!$D:$D,الاتشو!$C:$C,$A7,الاتشو!$F:$F,"<>")-SUMIFS(الاتشو!$D:$D,الاتشو!$C:$C,$A7,الاتشو!$G:$G,"<>",الاتشو!$F:$F,"")) -> 0 | E7: =IF($A7="","",SUMIFS('علاء بوم ارض النت'!$D:$D,'علاء بوم ارض النت'!$C:$C,$A7,'علاء بوم ارض النت'!$F:$F,"<>")-SUMIFS('علاء بوم ارض النت'!$D:$D,'علاء بوم ارض النت'!$C:$C,$A7,'علاء بوم ارض النت'!$G:$G,"<>",'علاء بوم ارض النت'!$F:$F,"")) -> 24 | F7: =IF($A7="","",SUMIFS('كيمو ميت ابو خالد'!$D:$D,'كيمو ميت ابو خالد'!$C:$C,$A7,'كيمو ميت ابو خالد'!$F:$F,"<>")-SUMIFS('كيمو ميت ابو خالد'!$D:$D,'كيمو ميت ابو خالد'!$C:$C,$A7,'كيمو ميت ابو خالد'!$G:$G,"<>",'كيمو ميت ابو خالد'!$F:$F,"")) -> 0 | G7: =IF($A7="","",SUMIFS(KAZO!$D:$D,KAZO!$C:$C,$A7,KAZO!$F:$F,"<>")-SUMIFS(KAZO!$D:$D,KAZO!$C:$C,$A7,KAZO!$G:$G,"<>",KAZO!$F:$F,"")) -> 0 | H7: =IF($A7="","",SUMIFS(LAFY!$D:$D,LAFY!$C:$C,$A7,LAFY!$F:$F,"<>")-SUMIFS(LAFY!$D:$D,LAFY!$C:$C,$A7,LAFY!$G:$G,"<>",LAFY!$F:$F,"")) -> 24 | I7: =IF($A7="","",SUMIFS('POINT زفتي (جديد)'!$D:$D,'POINT زفتي (جديد)'!$C:$C,$A7,'POINT زفتي (جديد)'!$F:$F,"<>")-SUMIFS('POINT زفتي (جديد)'!$D:$D,'POINT زفتي (جديد)'!$C:$C,$A7,'POINT زفتي (جديد)'!$G:$G,"<>",'POINT زفتي (جديد)'!$F:$F,"")) -> 0 | J7: =IF($A7="","",SUMIFS('POINT سعد زغلول (قديم)'!$D:$D,'POINT سعد زغلول (قديم)'!$C:$C,$A7,'POINT سعد زغلول (قديم)'!$F:$F,"<>")-SUMIFS('POINT سعد زغلول (قديم)'!$D:$D,'POINT سعد زغلول (قديم)'!$C:$C,$A7,'POINT سعد زغلول (قديم)'!$G:$G,"<>",'POINT سعد زغلول (قديم)'!$F:$F,"")) -> 0 | K7: =IF($A7="","",SUMIFS('POWER ارض النت'!$D:$D,'POWER ارض النت'!$C:$C,$A7,'POWER ارض النت'!$F:$F,"<>")-SUMIFS('POWER ارض النت'!$D:$D,'POWER ارض النت'!$C:$C,$A7,'POWER ارض النت'!$G:$G,"<>",'POWER ارض النت'!$F:$F,"")) -> 0 | L7: =IF($A7="","",SUMIFS('POWER زفتي'!$D:$D,'POWER زفتي'!$C:$C,$A7,'POWER زفتي'!$F:$F,"<>")-SUMIFS('POWER زفتي'!$D:$D,'POWER زفتي'!$C:$C,$A7,'POWER زفتي'!$G:$G,"<>",'POWER زفتي'!$F:$F,"")) -> 8 | M7: =IF($A7="","",SUMIFS('احمد المنوفي'!$D:$D,'احمد المنوفي'!$C:$C,$A7,'احمد المنوفي'!$F:$F,"<>")-SUMIFS('احمد المنوفي'!$D:$D,'احمد المنوفي'!$C:$C,$A7,'احمد المنوفي'!$G:$G,"<>",'احمد المنوفي'!$F:$F,"")) -> 0 | N7: =IF($A7="","",SUMIFS(السفير!$D:$D,السفير!$C:$C,$A7,السفير!$F:$F,"<>")-SUMIFS(السفير!$D:$D,السفير!$C:$C,$A7,السفير!$G:$G,"<>",السفير!$F:$F,"")) -> 0 | O7: =IF($A7="","",SUMIFS(العالمي!$D:$D,العالمي!$C:$C,$A7,العالمي!$F:$F,"<>")-SUMIFS(العالمي!$D:$D,العالمي!$C:$C,$A7,العالمي!$G:$G,"<>",العالمي!$F:$F,"")) -> 0 | P7: =IF($A7="","",SUMIFS('باهي التركي'!$D:$D,'باهي التركي'!$C:$C,$A7,'باهي التركي'!$F:$F,"<>")-SUMIFS('باهي التركي'!$D:$D,'باهي التركي'!$C:$C,$A7,'باهي التركي'!$G:$G,"<>",'باهي التركي'!$F:$F,"")) -> 0 | Q7: =IF($A7="","",SUMIFS('توتي دماص'!$D:$D,'توتي دماص'!$C:$C,$A7,'توتي دماص'!$F:$F,"<>")-SUMIFS('توتي دماص'!$D:$D,'توتي دماص'!$C:$C,$A7,'توتي دماص'!$G:$G,"<>",'توتي دماص'!$F:$F,"")) -> 0 | R7: =IF($A7="","",SUMIFS('رضا محمد'!$D:$D,'رضا محمد'!$C:$C,$A7,'رضا محمد'!$F:$F,"<>")-SUMIFS('رضا محمد'!$D:$D,'رضا محمد'!$C:$C,$A7,'رضا محمد'!$G:$G,"<>",'رضا محمد'!$F:$F,"")) -> 0 | S7: =IF($A7="","",SUMIFS('زومبي العشري'!$D:$D,'زومبي العشري'!$C:$C,$A7,'زومبي العشري'!$F:$F,"<>")-SUMIFS('زومبي العشري'!$D:$D,'زومبي العشري'!$C:$C,$A7,'زومبي العشري'!$G:$G,"<>",'زومبي العشري'!$F:$F,"")) -> 0 | T7: =IF($A7="","",SUMIFS('محمد عرابي'!$D:$D,'محمد عرابي'!$C:$C,$A7,'محمد عرابي'!$F:$F,"<>")-SUMIFS('محمد عرابي'!$D:$D,'محمد عرابي'!$C:$C,$A7,'محمد عرابي'!$G:$G,"<>",'محمد عرابي'!$F:$F,"")) -> 0 | U7: =IF($A7="","",SUMIFS('عم جمال'!$D:$D,'عم جمال'!$C:$C,$A7,'عم جمال'!$F:$F,"<>")-SUMIFS('عم جمال'!$D:$D,'عم جمال'!$C:$C,$A7,'عم جمال'!$G:$G,"<>",'عم جمال'!$F:$F,"")) -> 4 | V7: =IF($A7="","",SUMIFS('فاير سيليكت'!$D:$D,'فاير سيليكت'!$C:$C,$A7,'فاير سيليكت'!$F:$F,"<>")-SUMIFS('فاير سيليكت'!$D:$D,'فاير سيليكت'!$C:$C,$A7,'فاير سيليكت'!$G:$G,"<>",'فاير سيليكت'!$F:$F,"")) -> 0 | W7: =IF($A7="","",SUMIFS(فرانكو!$D:$D,فرانكو!$C:$C,$A7,فرانكو!$F:$F,"<>")-SUMIFS(فرانكو!$D:$D,فرانكو!$C:$C,$A7,فرانكو!$G:$G,"<>",فرانكو!$F:$F,"")) -> 0 | X7: =IF($A7="","",SUMIFS('كريم بكر'!$D:$D,'كريم بكر'!$C:$C,$A7,'كريم بكر'!$F:$F,"<>")-SUMIFS('كريم بكر'!$D:$D,'كريم بكر'!$C:$C,$A7,'كريم بكر'!$G:$G,"<>",'كريم بكر'!$F:$F,"")) -> 0 | Y7: =IF($A7="","",SUMIFS(بفرا!$D:$D,بفرا!$C:$C,$A7,بفرا!$F:$F,"<>")-SUMIFS(بفرا!$D:$D,بفرا!$C:$C,$A7,بفرا!$G:$G,"<>",بفرا!$F:$F,"")) -> 0 | Z7: =IF($A7="","",SUMIFS('محل كوم النور'!$D:$D,'محل كوم النور'!$C:$C,$A7,'محل كوم النور'!$F:$F,"<>")-SUMIFS('محل كوم النور'!$D:$D,'محل كوم النور'!$C:$C,$A7,'محل كوم النور'!$G:$G,"<>",'محل كوم النور'!$F:$F,"")) -> 0 | AA7: =IF($A7="","",SUMIFS('محمد النجار'!$D:$D,'محمد النجار'!$C:$C,$A7,'محمد النجار'!$F:$F,"<>")-SUMIFS('محمد النجار'!$D:$D,'محمد النجار'!$C:$C,$A7,'محمد النجار'!$G:$G,"<>",'محمد النجار'!$F:$F,"")) -> 0 | AB7: =IF($A7="","",SUMIFS('محمود عبدالرسول'!$D:$D,'محمود عبدالرسول'!$C:$C,$A7,'محمود عبدالرسول'!$F:$F,"<>")-SUMIFS('محمود عبدالرسول'!$D:$D,'محمود عبدالرسول'!$C:$C,$A7,'محمود عبدالرسول'!$G:$G,"<>",'محمود عبدالرسول'!$F:$F,"")) -> 0 | AC7: =IF($A7="","",SUMIFS('مول المصطفي'!$D:$D,'مول المصطفي'!$C:$C,$A7,'مول المصطفي'!$F:$F,"<>")-SUMIFS('مول المصطفي'!$D:$D,'مول المصطفي'!$C:$C,$A7,'مول المصطفي'!$G:$G,"<>",'مول المصطفي'!$F:$F,"")) -> 0 | AD7: =IF($A7="","",SUMIFS(مصانع!$D:$D,مصانع!$C:$C,$A7,مصانع!$F:$F,"<>")-SUMIFS(مصانع!$D:$D,مصانع!$C:$C,$A7,مصانع!$G:$G,"<>",مصانع!$F:$F,"")) -> 0 | AE7: =IF($A7="","",SUM(B7:AD7)) -> 60 | AF7: شروال شريط اوفر سايز | AG7: 60 | AH7: =IF(OR($A7="",AG7=""),"",AG7-AE7) -> 0 | AI7: 365 | AJ7: =IF(OR($A7="",AH7=""),"",AH7*AI7) -> 0
A8: B102 | B8: =IF($A8="","",SUMIFS('4K حموده'!$D:$D,'4K حموده'!$C:$C,$A8,'4K حموده'!$F:$F,"<>")-SUMIFS('4K حموده'!$D:$D,'4K حموده'!$C:$C,$A8,'4K حموده'!$G:$G,"<>",'4K حموده'!$F:$F,"")) -> 4 | C8: =IF($A8="","",SUMIFS('مكتب القاضي'!$D:$D,'مكتب القاضي'!$C:$C,$A8,'مكتب القاضي'!$F:$F,"<>")-SUMIFS('مكتب القاضي'!$D:$D,'مكتب القاضي'!$C:$C,$A8,'مكتب القاضي'!$G:$G,"<>",'مكتب القاضي'!$F:$F,"")) -> 0 | D8: =IF($A8="","",SUMIFS(الاتشو!$D:$D,الاتشو!$C:$C,$A8,الاتشو!$F:$F,"<>")-SUMIFS(الاتشو!$D:$D,الاتشو!$C:$C,$A8,الاتشو!$G:$G,"<>",الاتشو!$F:$F,"")) -> 0 | E8: =IF($A8="","",SUMIFS('علاء بوم ارض النت'!$D:$D,'علاء بوم ارض النت'!$C:$C,$A8,'علاء بوم ارض النت'!$F:$F,"<>")-SUMIFS('علاء بوم ارض النت'!$D:$D,'علاء بوم ارض النت'!$C:$C,$A8,'علاء بوم ارض النت'!$G:$G,"<>",'علاء بوم ارض النت'!$F:$F,"")) -> 20 | F8: =IF($A8="","",SUMIFS('كيمو ميت ابو خالد'!$D:$D,'كيمو ميت ابو خالد'!$C:$C,$A8,'كيمو ميت ابو خالد'!$F:$F,"<>")-SUMIFS('كيمو ميت ابو خالد'!$D:$D,'كيمو ميت ابو خالد'!$C:$C,$A8,'كيمو ميت ابو خالد'!$G:$G,"<>",'كيمو ميت ابو خالد'!$F:$F,"")) -> 0 | G8: =IF($A8="","",SUMIFS(KAZO!$D:$D,KAZO!$C:$C,$A8,KAZO!$F:$F,"<>")-SUMIFS(KAZO!$D:$D,KAZO!$C:$C,$A8,KAZO!$G:$G,"<>",KAZO!$F:$F,"")) -> 0 | H8: =IF($A8="","",SUMIFS(LAFY!$D:$D,LAFY!$C:$C,$A8,LAFY!$F:$F,"<>")-SUMIFS(LAFY!$D:$D,LAFY!$C:$C,$A8,LAFY!$G:$G,"<>",LAFY!$F:$F,"")) -> 0 | I8: =IF($A8="","",SUMIFS('POINT زفتي (جديد)'!$D:$D,'POINT زفتي (جديد)'!$C:$C,$A8,'POINT زفتي (جديد)'!$F:$F,"<>")-SUMIFS('POINT زفتي (جديد)'!$D:$D,'POINT زفتي (جديد)'!$C:$C,$A8,'POINT زفتي (جديد)'!$G:$G,"<>",'POINT زفتي (جديد)'!$F:$F,"")) -> 0 | J8: =IF($A8="","",SUMIFS('POINT سعد زغلول (قديم)'!$D:$D,'POINT سعد زغلول (قديم)'!$C:$C,$A8,'POINT سعد زغلول (قديم)'!$F:$F,"<>")-SUMIFS('POINT سعد زغلول (قديم)'!$D:$D,'POINT سعد زغلول (قديم)'!$C:$C,$A8,'POINT سعد زغلول (قديم)'!$G:$G,"<>",'POINT سعد زغلول (قديم)'!$F:$F,"")) -> 0 | K8: =IF($A8="","",SUMIFS('POWER ارض النت'!$D:$D,'POWER ارض النت'!$C:$C,$A8,'POWER ارض النت'!$F:$F,"<>")-SUMIFS('POWER ارض النت'!$D:$D,'POWER ارض النت'!$C:$C,$A8,'POWER ارض النت'!$G:$G,"<>",'POWER ارض النت'!$F:$F,"")) -> 0 | L8: =IF($A8="","",SUMIFS('POWER زفتي'!$D:$D,'POWER زفتي'!$C:$C,$A8,'POWER زفتي'!$F:$F,"<>")-SUMIFS('POWER زفتي'!$D:$D,'POWER زفتي'!$C:$C,$A8,'POWER زفتي'!$G:$G,"<>",'POWER زفتي'!$F:$F,"")) -> 0 | M8: =IF($A8="","",SUMIFS('احمد المنوفي'!$D:$D,'احمد المنوفي'!$C:$C,$A8,'احمد المنوفي'!$F:$F,"<>")-SUMIFS('احمد المنوفي'!$D:$D,'احمد المنوفي'!$C:$C,$A8,'احمد المنوفي'!$G:$G,"<>",'احمد المنوفي'!$F:$F,"")) -> 16 | N8: =IF($A8="","",SUMIFS(السفير!$D:$D,السفير!$C:$C,$A8,السفير!$F:$F,"<>")-SUMIFS(السفير!$D:$D,السفير!$C:$C,$A8,السفير!$G:$G,"<>",السفير!$F:$F,"")) -> 0 | O8: =IF($A8="","",SUMIFS(العالمي!$D:$D,العالمي!$C:$C,$A8,العالمي!$F:$F,"<>")-SUMIFS(العالمي!$D:$D,العالمي!$C:$C,$A8,العالمي!$G:$G,"<>",العالمي!$F:$F,"")) -> 0 | P8: =IF($A8="","",SUMIFS('باهي التركي'!$D:$D,'باهي التركي'!$C:$C,$A8,'باهي التركي'!$F:$F,"<>")-SUMIFS('باهي التركي'!$D:$D,'باهي التركي'!$C:$C,$A8,'باهي التركي'!$G:$G,"<>",'باهي التركي'!$F:$F,"")) -> 0 | Q8: =IF($A8="","",SUMIFS('توتي دماص'!$D:$D,'توتي دماص'!$C:$C,$A8,'توتي دماص'!$F:$F,"<>")-SUMIFS('توتي دماص'!$D:$D,'توتي دماص'!$C:$C,$A8,'توتي دماص'!$G:$G,"<>",'توتي دماص'!$F:$F,"")) -> 0 | R8: =IF($A8="","",SUMIFS('رضا محمد'!$D:$D,'رضا محمد'!$C:$C,$A8,'رضا محمد'!$F:$F,"<>")-SUMIFS('رضا محمد'!$D:$D,'رضا محمد'!$C:$C,$A8,'رضا محمد'!$G:$G,"<>",'رضا محمد'!$F:$F,"")) -> 0 | S8: =IF($A8="","",SUMIFS('زومبي العشري'!$D:$D,'زومبي العشري'!$C:$C,$A8,'زومبي العشري'!$F:$F,"<>")-SUMIFS('زومبي العشري'!$D:$D,'زومبي العشري'!$C:$C,$A8,'زومبي العشري'!$G:$G,"<>",'زومبي العشري'!$F:$F,"")) -> 0 | T8: =IF($A8="","",SUMIFS('محمد عرابي'!$D:$D,'محمد عرابي'!$C:$C,$A8,'محمد عرابي'!$F:$F,"<>")-SUMIFS('محمد عرابي'!$D:$D,'محمد عرابي'!$C:$C,$A8,'محمد عرابي'!$G:$G,"<>",'محمد عرابي'!$F:$F,"")) -> 0 | U8: =IF($A8="","",SUMIFS('عم جمال'!$D:$D,'عم جمال'!$C:$C,$A8,'عم جمال'!$F:$F,"<>")-SUMIFS('عم جمال'!$D:$D,'عم جمال'!$C:$C,$A8,'عم جمال'!$G:$G,"<>",'عم جمال'!$F:$F,"")) -> 0 | V8: =IF($A8="","",SUMIFS('فاير سيليكت'!$D:$D,'فاير سيليكت'!$C:$C,$A8,'فاير سيليكت'!$F:$F,"<>")-SUMIFS('فاير سيليكت'!$D:$D,'فاير سيليكت'!$C:$C,$A8,'فاير سيليكت'!$G:$G,"<>",'فاير سيليكت'!$F:$F,"")) -> 0 | W8: =IF($A8="","",SUMIFS(فرانكو!$D:$D,فرانكو!$C:$C,$A8,فرانكو!$F:$F,"<>")-SUMIFS(فرانكو!$D:$D,فرانكو!$C:$C,$A8,فرانكو!$G:$G,"<>",فرانكو!$F:$F,"")) -> 0 | X8: =IF($A8="","",SUMIFS('كريم بكر'!$D:$D,'كريم بكر'!$C:$C,$A8,'كريم بكر'!$F:$F,"<>")-SUMIFS('كريم بكر'!$D:$D,'كريم بكر'!$C:$C,$A8,'كريم بكر'!$G:$G,"<>",'كريم بكر'!$F:$F,"")) -> 0 | Y8: =IF($A8="","",SUMIFS(بفرا!$D:$D,بفرا!$C:$C,$A8,بفرا!$F:$F,"<>")-SUMIFS(بفرا!$D:$D,بفرا!$C:$C,$A8,بفرا!$G:$G,"<>",بفرا!$F:$F,"")) -> 0 | Z8: =IF($A8="","",SUMIFS('محل كوم النور'!$D:$D,'محل كوم النور'!$C:$C,$A8,'محل كوم النور'!$F:$F,"<>")-SUMIFS('محل كوم النور'!$D:$D,'محل كوم النور'!$C:$C,$A8,'محل كوم النور'!$G:$G,"<>",'محل كوم النور'!$F:$F,"")) -> 0 | AA8: =IF($A8="","",SUMIFS('محمد النجار'!$D:$D,'محمد النجار'!$C:$C,$A8,'محمد النجار'!$F:$F,"<>")-SUMIFS('محمد النجار'!$D:$D,'محمد النجار'!$C:$C,$A8,'محمد النجار'!$G:$G,"<>",'محمد النجار'!$F:$F,"")) -> 0 | AB8: =IF($A8="","",SUMIFS('محمود عبدالرسول'!$D:$D,'محمود عبدالرسول'!$C:$C,$A8,'محمود عبدالرسول'!$F:$F,"<>")-SUMIFS('محمود عبدالرسول'!$D:$D,'محمود عبدالرسول'!$C:$C,$A8,'محمود عبدالرسول'!$G:$G,"<>",'محمود عبدالرسول'!$F:$F,"")) -> 0 | AC8: =IF($A8="","",SUMIFS('مول المصطفي'!$D:$D,'مول المصطفي'!$C:$C,$A8,'مول المصطفي'!$F:$F,"<>")-SUMIFS('مول المصطفي'!$D:$D,'مول المصطفي'!$C:$C,$A8,'مول المصطفي'!$G:$G,"<>",'مول المصطفي'!$F:$F,"")) -> 0 | AD8: =IF($A8="","",SUMIFS(مصانع!$D:$D,مصانع!$C:$C,$A8,مصانع!$F:$F,"<>")-SUMIFS(مصانع!$D:$D,مصانع!$C:$C,$A8,مصانع!$G:$G,"<>",مصانع!$F:$F,"")) -> 0 | AE8: =IF($A8="","",SUM(B8:AD8)) -> 40 | AF8: شروال اديداس | AG8: 92 | AH8: =IF(OR($A8="",AG8=""),"",AG8-AE8) -> 52 | AI8: 350 | AJ8: =IF(OR($A8="",AH8=""),"",AH8*AI8) -> 18200
A9: B103 | B9: =IF($A9="","",SUMIFS('4K حموده'!$D:$D,'4K حموده'!$C:$C,$A9,'4K حموده'!$F:$F,"<>")-SUMIFS('4K حموده'!$D:$D,'4K حموده'!$C:$C,$A9,'4K حموده'!$G:$G,"<>",'4K حموده'!$F:$F,"")) -> 8 | C9: =IF($A9="","",SUMIFS('مكتب القاضي'!$D:$D,'مكتب القاضي'!$C:$C,$A9,'مكتب القاضي'!$F:$F,"<>")-SUMIFS('مكتب القاضي'!$D:$D,'مكتب القاضي'!$C:$C,$A9,'مكتب القاضي'!$G:$G,"<>",'مكتب القاضي'!$F:$F,"")) -> 0 | D9: =IF($A9="","",SUMIFS(الاتشو!$D:$D,الاتشو!$C:$C,$A9,الاتشو!$F:$F,"<>")-SUMIFS(الاتشو!$D:$D,الاتشو!$C:$C,$A9,الاتشو!$G:$G,"<>",الاتشو!$F:$F,"")) -> 0 | E9: =IF($A9="","",SUMIFS('علاء بوم ارض النت'!$D:$D,'علاء بوم ارض النت'!$C:$C,$A9,'علاء بوم ارض النت'!$F:$F,"<>")-SUMIFS('علاء بوم ارض النت'!$D:$D,'علاء بوم ارض النت'!$C:$C,$A9,'علاء بوم ارض النت'!$G:$G,"<>",'علاء بوم ارض النت'!$F:$F,"")) -> 24 | F9: =IF($A9="","",SUMIFS('كيمو ميت ابو خالد'!$D:$D,'كيمو ميت ابو خالد'!$C:$C,$A9,'كيمو ميت ابو خالد'!$F:$F,"<>")-SUMIFS('كيمو ميت ابو خالد'!$D:$D,'كيمو ميت ابو خالد'!$C:$C,$A9,'كيمو ميت ابو خالد'!$G:$G,"<>",'كيمو ميت ابو خالد'!$F:$F,"")) -> 0 | G9: =IF($A9="","",SUMIFS(KAZO!$D:$D,KAZO!$C:$C,$A9,KAZO!$F:$F,"<>")-SUMIFS(KAZO!$D:$D,KAZO!$C:$C,$A9,KAZO!$G:$G,"<>",KAZO!$F:$F,"")) -> 0 | H9: =IF($A9="","",SUMIFS(LAFY!$D:$D,LAFY!$C:$C,$A9,LAFY!$F:$F,"<>")-SUMIFS(LAFY!$D:$D,LAFY!$C:$C,$A9,LAFY!$G:$G,"<>",LAFY!$F:$F,"")) -> 36 | I9: =IF($A9="","",SUMIFS('POINT زفتي (جديد)'!$D:$D,'POINT زفتي (جديد)'!$C:$C,$A9,'POINT زفتي (جديد)'!$F:$F,"<>")-SUMIFS('POINT زفتي (جديد)'!$D:$D,'POINT زفتي (جديد)'!$C:$C,$A9,'POINT زفتي (جديد)'!$G:$G,"<>",'POINT زفتي (جديد)'!$F:$F,"")) -> 0 | J9: =IF($A9="","",SUMIFS('POINT سعد زغلول (قديم)'!$D:$D,'POINT سعد زغلول (قديم)'!$C:$C,$A9,'POINT سعد زغلول (قديم)'!$F:$F,"<>")-SUMIFS('POINT سعد زغلول (قديم)'!$D:$D,'POINT سعد زغلول (قديم)'!$C:$C,$A9,'POINT سعد زغلول (قديم)'!$G:$G,"<>",'POINT سعد زغلول (قديم)'!$F:$F,"")) -> 0 | K9: =IF($A9="","",SUMIFS('POWER ارض النت'!$D:$D,'POWER ارض النت'!$C:$C,$A9,'POWER ارض النت'!$F:$F,"<>")-SUMIFS('POWER ارض النت'!$D:$D,'POWER ارض النت'!$C:$C,$A9,'POWER ارض النت'!$G:$G,"<>",'POWER ارض النت'!$F:$F,"")) -> 0 | L9: =IF($A9="","",SUMIFS('POWER زفتي'!$D:$D,'POWER زفتي'!$C:$C,$A9,'POWER زفتي'!$F:$F,"<>")-SUMIFS('POWER زفتي'!$D:$D,'POWER زفتي'!$C:$C,$A9,'POWER زفتي'!$G:$G,"<>",'POWER زفتي'!$F:$F,"")) -> 0 | M9: =IF($A9="","",SUMIFS('احمد المنوفي'!$D:$D,'احمد المنوفي'!$C:$C,$A9,'احمد المنوفي'!$F:$F,"<>")-SUMIFS('احمد المنوفي'!$D:$D,'احمد المنوفي'!$C:$C,$A9,'احمد المنوفي'!$G:$G,"<>",'احمد المنوفي'!$F:$F,"")) -> 0 | N9: =IF($A9="","",SUMIFS(السفير!$D:$D,السفير!$C:$C,$A9,السفير!$F:$F,"<>")-SUMIFS(السفير!$D:$D,السفير!$C:$C,$A9,السفير!$G:$G,"<>",السفير!$F:$F,"")) -> 0 | O9: =IF($A9="","",SUMIFS(العالمي!$D:$D,العالمي!$C:$C,$A9,العالمي!$F:$F,"<>")-SUMIFS(العالمي!$D:$D,العالمي!$C:$C,$A9,العالمي!$G:$G,"<>",العالمي!$F:$F,"")) -> 0 | P9: =IF($A9="","",SUMIFS('باهي التركي'!$D:$D,'باهي التركي'!$C:$C,$A9,'باهي التركي'!$F:$F,"<>")-SUMIFS('باهي التركي'!$D:$D,'باهي التركي'!$C:$C,$A9,'باهي التركي'!$G:$G,"<>",'باهي التركي'!$F:$F,"")) -> 0 | Q9: =IF($A9="","",SUMIFS('توتي دماص'!$D:$D,'توتي دماص'!$C:$C,$A9,'توتي دماص'!$F:$F,"<>")-SUMIFS('توتي دماص'!$D:$D,'توتي دماص'!$C:$C,$A9,'توتي دماص'!$G:$G,"<>",'توتي دماص'!$F:$F,"")) -> 0 | R9: =IF($A9="","",SUMIFS('رضا محمد'!$D:$D,'رضا محمد'!$C:$C,$A9,'رضا محمد'!$F:$F,"<>")-SUMIFS('رضا محمد'!$D:$D,'رضا محمد'!$C:$C,$A9,'رضا محمد'!$G:$G,"<>",'رضا محمد'!$F:$F,"")) -> 0 | S9: =IF($A9="","",SUMIFS('زومبي العشري'!$D:$D,'زومبي العشري'!$C:$C,$A9,'زومبي العشري'!$F:$F,"<>")-SUMIFS('زومبي العشري'!$D:$D,'زومبي العشري'!$C:$C,$A9,'زومبي العشري'!$G:$G,"<>",'زومبي العشري'!$F:$F,"")) -> 0 | T9: =IF($A9="","",SUMIFS('محمد عرابي'!$D:$D,'محمد عرابي'!$C:$C,$A9,'محمد عرابي'!$F:$F,"<>")-SUMIFS('محمد عرابي'!$D:$D,'محمد عرابي'!$C:$C,$A9,'محمد عرابي'!$G:$G,"<>",'محمد عرابي'!$F:$F,"")) -> 1 | U9: =IF($A9="","",SUMIFS('عم جمال'!$D:$D,'عم جمال'!$C:$C,$A9,'عم جمال'!$F:$F,"<>")-SUMIFS('عم جمال'!$D:$D,'عم جمال'!$C:$C,$A9,'عم جمال'!$G:$G,"<>",'عم جمال'!$F:$F,"")) -> 0 | V9: =IF($A9="","",SUMIFS('فاير سيليكت'!$D:$D,'فاير سيليكت'!$C:$C,$A9,'فاير سيليكت'!$F:$F,"<>")-SUMIFS('فاير سيليكت'!$D:$D,'فاير سيليكت'!$C:$C,$A9,'فاير سيليكت'!$G:$G,"<>",'فاير سيليكت'!$F:$F,"")) -> 0 | W9: =IF($A9="","",SUMIFS(فرانكو!$D:$D,فرانكو!$C:$C,$A9,فرانكو!$F:$F,"<>")-SUMIFS(فرانكو!$D:$D,فرانكو!$C:$C,$A9,فرانكو!$G:$G,"<>",فرانكو!$F:$F,"")) -> 0 | X9: =IF($A9="","",SUMIFS('كريم بكر'!$D:$D,'كريم بكر'!$C:$C,$A9,'كريم بكر'!$F:$F,"<>")-SUMIFS('كريم بكر'!$D:$D,'كريم بكر'!$C:$C,$A9,'كريم بكر'!$G:$G,"<>",'كريم بكر'!$F:$F,"")) -> 0 | Y9: =IF($A9="","",SUMIFS(بفرا!$D:$D,بفرا!$C:$C,$A9,بفرا!$F:$F,"<>")-SUMIFS(بفرا!$D:$D,بفرا!$C:$C,$A9,بفرا!$G:$G,"<>",بفرا!$F:$F,"")) -> 0 | Z9: =IF($A9="","",SUMIFS('محل كوم النور'!$D:$D,'محل كوم النور'!$C:$C,$A9,'محل كوم النور'!$F:$F,"<>")-SUMIFS('محل كوم النور'!$D:$D,'محل كوم النور'!$C:$C,$A9,'محل كوم النور'!$G:$G,"<>",'محل كوم النور'!$F:$F,"")) -> 0 | AA9: =IF($A9="","",SUMIFS('محمد النجار'!$D:$D,'محمد النجار'!$C:$C,$A9,'محمد النجار'!$F:$F,"<>")-SUMIFS('محمد النجار'!$D:$D,'محمد النجار'!$C:$C,$A9,'محمد النجار'!$G:$G,"<>",'محمد النجار'!$F:$F,"")) -> 0 | AB9: =IF($A9="","",SUMIFS('محمود عبدالرسول'!$D:$D,'محمود عبدالرسول'!$C:$C,$A9,'محمود عبدالرسول'!$F:$F,"<>")-SUMIFS('محمود عبدالرسول'!$D:$D,'محمود عبدالرسول'!$C:$C,$A9,'محمود عبدالرسول'!$G:$G,"<>",'محمود عبدالرسول'!$F:$F,"")) -> 0 | AC9: =IF($A9="","",SUMIFS('مول المصطفي'!$D:$D,'مول المصطفي'!$C:$C,$A9,'مول المصطفي'!$F:$F,"<>")-SUMIFS('مول المصطفي'!$D:$D,'مول المصطفي'!$C:$C,$A9,'مول المصطفي'!$G:$G,"<>",'مول المصطفي'!$F:$F,"")) -> 0 | AD9: =IF($A9="","",SUMIFS(مصانع!$D:$D,مصانع!$C:$C,$A9,مصانع!$F:$F,"<>")-SUMIFS(مصانع!$D:$D,مصانع!$C:$C,$A9,مصانع!$G:$G,"<>",مصانع!$F:$F,"")) -> 0 | AE9: =IF($A9="","",SUM(B9:AD9)) -> 69 | AF9: شروال انترلوك وايد ليج اديداس | AG9: 116 | AH9: =IF(OR($A9="",AG9=""),"",AG9-AE9) -> 47 | AI9: 390 | AJ9: =IF(OR($A9="",AH9=""),"",AH9*AI9) -> 18330
A10: B104 | B10: =IF($A10="","",SUMIFS('4K حموده'!$D:$D,'4K حموده'!$C:$C,$A10,'4K حموده'!$F:$F,"<>")-SUMIFS('4K حموده'!$D:$D,'4K حموده'!$C:$C,$A10,'4K حموده'!$G:$G,"<>",'4K حموده'!$F:$F,"")) -> 12 | C10: =IF($A10="","",SUMIFS('مكتب القاضي'!$D:$D,'مكتب القاضي'!$C:$C,$A10,'مكتب القاضي'!$F:$F,"<>")-SUMIFS('مكتب القاضي'!$D:$D,'مكتب القاضي'!$C:$C,$A10,'مكتب القاضي'!$G:$G,"<>",'مكتب القاضي'!$F:$F,"")) -> 0 | D10: =IF($A10="","",SUMIFS(الاتشو!$D:$D,الاتشو!$C:$C,$A10,الاتشو!$F:$F,"<>")-SUMIFS(الاتشو!$D:$D,الاتشو!$C:$C,$A10,الاتشو!$G:$G,"<>",الاتشو!$F:$F,"")) -> 0 | E10: =IF($A10="","",SUMIFS('علاء بوم ارض النت'!$D:$D,'علاء بوم ارض النت'!$C:$C,$A10,'علاء بوم ارض النت'!$F:$F,"<>")-SUMIFS('علاء بوم ارض النت'!$D:$D,'علاء بوم ارض النت'!$C:$C,$A10,'علاء بوم ارض النت'!$G:$G,"<>",'علاء بوم ارض النت'!$F:$F,"")) -> 23 | F10: =IF($A10="","",SUMIFS('كيمو ميت ابو خالد'!$D:$D,'كيمو ميت ابو خالد'!$C:$C,$A10,'كيمو ميت ابو خالد'!$F:$F,"<>")-SUMIFS('كيمو ميت ابو خالد'!$D:$D,'كيمو ميت ابو خالد'!$C:$C,$A10,'كيمو ميت ابو خالد'!$G:$G,"<>",'كيمو ميت ابو خالد'!$F:$F,"")) -> 0 | G10: =IF($A10="","",SUMIFS(KAZO!$D:$D,KAZO!$C:$C,$A10,KAZO!$F:$F,"<>")-SUMIFS(KAZO!$D:$D,KAZO!$C:$C,$A10,KAZO!$G:$G,"<>",KAZO!$F:$F,"")) -> 0 | H10: =IF($A10="","",SUMIFS(LAFY!$D:$D,LAFY!$C:$C,$A10,LAFY!$F:$F,"<>")-SUMIFS(LAFY!$D:$D,LAFY!$C:$C,$A10,LAFY!$G:$G,"<>",LAFY!$F:$F,"")) -> 36 | I10: =IF($A10="","",SUMIFS('POINT زفتي (جديد)'!$D:$D,'POINT زفتي (جديد)'!$C:$C,$A10,'POINT زفتي (جديد)'!$F:$F,"<>")-SUMIFS('POINT زفتي (جديد)'!$D:$D,'POINT زفتي (جديد)'!$C:$C,$A10,'POINT زفتي (جديد)'!$G:$G,"<>",'POINT زفتي (جديد)'!$F:$F,"")) -> 12 | J10: =IF($A10="","",SUMIFS('POINT سعد زغلول (قديم)'!$D:$D,'POINT سعد زغلول (قديم)'!$C:$C,$A10,'POINT سعد زغلول (قديم)'!$F:$F,"<>")-SUMIFS('POINT سعد زغلول (قديم)'!$D:$D,'POINT سعد زغلول (قديم)'!$C:$C,$A10,'POINT سعد زغلول (قديم)'!$G:$G,"<>",'POINT سعد زغلول (قديم)'!$F:$F,"")) -> 0 | K10: =IF($A10="","",SUMIFS('POWER ارض النت'!$D:$D,'POWER ارض النت'!$C:$C,$A10,'POWER ارض النت'!$F:$F,"<>")-SUMIFS('POWER ارض النت'!$D:$D,'POWER ارض النت'!$C:$C,$A10,'POWER ارض النت'!$G:$G,"<>",'POWER ارض النت'!$F:$F,"")) -> 0 | L10: =IF($A10="","",SUMIFS('POWER زفتي'!$D:$D,'POWER زفتي'!$C:$C,$A10,'POWER زفتي'!$F:$F,"<>")-SUMIFS('POWER زفتي'!$D:$D,'POWER زفتي'!$C:$C,$A10,'POWER زفتي'!$G:$G,"<>",'POWER زفتي'!$F:$F,"")) -> 12 | M10: =IF($A10="","",SUMIFS('احمد المنوفي'!$D:$D,'احمد المنوفي'!$C:$C,$A10,'احمد المنوفي'!$F:$F,"<>")-SUMIFS('احمد المنوفي'!$D:$D,'احمد المنوفي'!$C:$C,$A10,'احمد المنوفي'!$G:$G,"<>",'احمد المنوفي'!$F:$F,"")) -> 0 | N10: =IF($A10="","",SUMIFS(السفير!$D:$D,السفير!$C:$C,$A10,السفير!$F:$F,"<>")-SUMIFS(السفير!$D:$D,السفير!$C:$C,$A10,السفير!$G:$G,"<>",السفير!$F:$F,"")) -> 0 | O10: =IF($A10="","",SUMIFS(العالمي!$D:$D,العالمي!$C:$C,$A10,العالمي!$F:$F,"<>")-SUMIFS(العالمي!$D:$D,العالمي!$C:$C,$A10,العالمي!$G:$G,"<>",العالمي!$F:$F,"")) -> 0 | P10: =IF($A10="","",SUMIFS('باهي التركي'!$D:$D,'باهي التركي'!$C:$C,$A10,'باهي التركي'!$F:$F,"<>")-SUMIFS('باهي التركي'!$D:$D,'باهي التركي'!$C:$C,$A10,'باهي التركي'!$G:$G,"<>",'باهي التركي'!$F:$F,"")) -> 0 | Q10: =IF($A10="","",SUMIFS('توتي دماص'!$D:$D,'توتي دماص'!$C:$C,$A10,'توتي دماص'!$F:$F,"<>")-SUMIFS('توتي دماص'!$D:$D,'توتي دماص'!$C:$C,$A10,'توتي دماص'!$G:$G,"<>",'توتي دماص'!$F:$F,"")) -> 0 | R10: =IF($A10="","",SUMIFS('رضا محمد'!$D:$D,'رضا محمد'!$C:$C,$A10,'رضا محمد'!$F:$F,"<>")-SUMIFS('رضا محمد'!$D:$D,'رضا محمد'!$C:$C,$A10,'رضا محمد'!$G:$G,"<>",'رضا محمد'!$F:$F,"")) -> 0 | S10: =IF($A10="","",SUMIFS('زومبي العشري'!$D:$D,'زومبي العشري'!$C:$C,$A10,'زومبي العشري'!$F:$F,"<>")-SUMIFS('زومبي العشري'!$D:$D,'زومبي العشري'!$C:$C,$A10,'زومبي العشري'!$G:$G,"<>",'زومبي العشري'!$F:$F,"")) -> 0 | T10: =IF($A10="","",SUMIFS('محمد عرابي'!$D:$D,'محمد عرابي'!$C:$C,$A10,'محمد عرابي'!$F:$F,"<>")-SUMIFS('محمد عرابي'!$D:$D,'محمد عرابي'!$C:$C,$A10,'محمد عرابي'!$G:$G,"<>",'محمد عرابي'!$F:$F,"")) -> 8 | U10: =IF($A10="","",SUMIFS('عم جمال'!$D:$D,'عم جمال'!$C:$C,$A10,'عم جمال'!$F:$F,"<>")-SUMIFS('عم جمال'!$D:$D,'عم جمال'!$C:$C,$A10,'عم جمال'!$G:$G,"<>",'عم جمال'!$F:$F,"")) -> 20 | V10: =IF($A10="","",SUMIFS('فاير سيليكت'!$D:$D,'فاير سيليكت'!$C:$C,$A10,'فاير سيليكت'!$F:$F,"<>")-SUMIFS('فاير سيليكت'!$D:$D,'فاير سيليكت'!$C:$C,$A10,'فاير سيليكت'!$G:$G,"<>",'فاير سيليكت'!$F:$F,"")) -> 0 | W10: =IF($A10="","",SUMIFS(فرانكو!$D:$D,فرانكو!$C:$C,$A10,فرانكو!$F:$F,"<>")-SUMIFS(فرانكو!$D:$D,فرانكو!$C:$C,$A10,فرانكو!$G:$G,"<>",فرانكو!$F:$F,"")) -> 0 | X10: =IF($A10="","",SUMIFS('كريم بكر'!$D:$D,'كريم بكر'!$C:$C,$A10,'كريم بكر'!$F:$F,"<>")-SUMIFS('كريم بكر'!$D:$D,'كريم بكر'!$C:$C,$A10,'كريم بكر'!$G:$G,"<>",'كريم بكر'!$F:$F,"")) -> 0 | Y10: =IF($A10="","",SUMIFS(بفرا!$D:$D,بفرا!$C:$C,$A10,بفرا!$F:$F,"<>")-SUMIFS(بفرا!$D:$D,بفرا!$C:$C,$A10,بفرا!$G:$G,"<>",بفرا!$F:$F,"")) -> 0 | Z10: =IF($A10="","",SUMIFS('محل كوم النور'!$D:$D,'محل كوم النور'!$C:$C,$A10,'محل كوم النور'!$F:$F,"<>")-SUMIFS('محل كوم النور'!$D:$D,'محل كوم النور'!$C:$C,$A10,'محل كوم النور'!$G:$G,"<>",'محل كوم النور'!$F:$F,"")) -> 0 | AA10: =IF($A10="","",SUMIFS('محمد النجار'!$D:$D,'محمد النجار'!$C:$C,$A10,'محمد النجار'!$F:$F,"<>")-SUMIFS('محمد النجار'!$D:$D,'محمد النجار'!$C:$C,$A10,'محمد النجار'!$G:$G,"<>",'محمد النجار'!$F:$F,"")) -> 12 | AB10: =IF($A10="","",SUMIFS('محمود عبدالرسول'!$D:$D,'محمود عبدالرسول'!$C:$C,$A10,'محمود عبدالرسول'!$F:$F,"<>")-SUMIFS('محمود عبدالرسول'!$D:$D,'محمود عبدالرسول'!$C:$C,$A10,'محمود عبدالرسول'!$G:$G,"<>",'محمود عبدالرسول'!$F:$F,"")) -> 0 | AC10: =IF($A10="","",SUMIFS('مول المصطفي'!$D:$D,'مول المصطفي'!$C:$C,$A10,'مول المصطفي'!$F:$F,"<>")-SUMIFS('مول المصطفي'!$D:$D,'مول المصطفي'!$C:$C,$A10,'مول المصطفي'!$G:$G,"<>",'مول المصطفي'!$F:$F,"")) -> 0 | AD10: =IF($A10="","",SUMIFS(مصانع!$D:$D,مصانع!$C:$C,$A10,مصانع!$F:$F,"<>")-SUMIFS(مصانع!$D:$D,مصانع!$C:$C,$A10,مصانع!$G:$G,"<>",مصانع!$F:$F,"")) -> 0 | AE10: =IF($A10="","",SUM(B10:AD10)) -> 135 | AF10: شروال قصات انترلوك | AG10: 148 | AH10: =IF(OR($A10="",AG10=""),"",AG10-AE10) -> 13 | AI10: 350 | AJ10: =IF(OR($A10="",AH10=""),"",AH10*AI10) -> 4550
A11: B07 | B11: =IF($A11="","",SUMIFS('4K حموده'!$D:$D,'4K حموده'!$C:$C,$A11,'4K حموده'!$F:$F,"<>")-SUMIFS('4K حموده'!$D:$D,'4K حموده'!$C:$C,$A11,'4K حموده'!$G:$G,"<>",'4K حموده'!$F:$F,"")) -> 4 | C11: =IF($A11="","",SUMIFS('مكتب القاضي'!$D:$D,'مكتب القاضي'!$C:$C,$A11,'مكتب القاضي'!$F:$F,"<>")-SUMIFS('مكتب القاضي'!$D:$D,'مكتب القاضي'!$C:$C,$A11,'مكتب القاضي'!$G:$G,"<>",'مكتب القاضي'!$F:$F,"")) -> 0 | D11: =IF($A11="","",SUMIFS(الاتشو!$D:$D,الاتشو!$C:$C,$A11,الاتشو!$F:$F,"<>")-SUMIFS(الاتشو!$D:$D,الاتشو!$C:$C,$A11,الاتشو!$G:$G,"<>",الاتشو!$F:$F,"")) -> 0 | E11: =IF($A11="","",SUMIFS('علاء بوم ارض النت'!$D:$D,'علاء بوم ارض النت'!$C:$C,$A11,'علاء بوم ارض النت'!$F:$F,"<>")-SUMIFS('علاء بوم ارض النت'!$D:$D,'علاء بوم ارض النت'!$C:$C,$A11,'علاء بوم ارض النت'!$G:$G,"<>",'علاء بوم ارض النت'!$F:$F,"")) -> 28 | F11: =IF($A11="","",SUMIFS('كيمو ميت ابو خالد'!$D:$D,'كيمو ميت ابو خالد'!$C:$C,$A11,'كيمو ميت ابو خالد'!$F:$F,"<>")-SUMIFS('كيمو ميت ابو خالد'!$D:$D,'كيمو ميت ابو خالد'!$C:$C,$A11,'كيمو ميت ابو خالد'!$G:$G,"<>",'كيمو ميت ابو خالد'!$F:$F,"")) -> 0 | G11: =IF($A11="","",SUMIFS(KAZO!$D:$D,KAZO!$C:$C,$A11,KAZO!$F:$F,"<>")-SUMIFS(KAZO!$D:$D,KAZO!$C:$C,$A11,KAZO!$G:$G,"<>",KAZO!$F:$F,"")) -> 0 | H11: =IF($A11="","",SUMIFS(LAFY!$D:$D,LAFY!$C:$C,$A11,LAFY!$F:$F,"<>")-SUMIFS(LAFY!$D:$D,LAFY!$C:$C,$A11,LAFY!$G:$G,"<>",LAFY!$F:$F,"")) -> 0 | I11: =IF($A11="","",SUMIFS('POINT زفتي (جديد)'!$D:$D,'POINT زفتي (جديد)'!$C:$C,$A11,'POINT زفتي (جديد)'!$F:$F,"<>")-SUMIFS('POINT زفتي (جديد)'!$D:$D,'POINT زفتي (جديد)'!$C:$C,$A11,'POINT زفتي (جديد)'!$G:$G,"<>",'POINT زفتي (جديد)'!$F:$F,"")) -> 4 | J11: =IF($A11="","",SUMIFS('POINT سعد زغلول (قديم)'!$D:$D,'POINT سعد زغلول (قديم)'!$C:$C,$A11,'POINT سعد زغلول (قديم)'!$F:$F,"<>")-SUMIFS('POINT سعد زغلول (قديم)'!$D:$D,'POINT سعد زغلول (قديم)'!$C:$C,$A11,'POINT سعد زغلول (قديم)'!$G:$G,"<>",'POINT سعد زغلول (قديم)'!$F:$F,"")) -> 0 | K11: =IF($A11="","",SUMIFS('POWER ارض النت'!$D:$D,'POWER ارض النت'!$C:$C,$A11,'POWER ارض النت'!$F:$F,"<>")-SUMIFS('POWER ارض النت'!$D:$D,'POWER ارض النت'!$C:$C,$A11,'POWER ارض النت'!$G:$G,"<>",'POWER ارض النت'!$F:$F,"")) -> 0 | L11: =IF($A11="","",SUMIFS('POWER زفتي'!$D:$D,'POWER زفتي'!$C:$C,$A11,'POWER زفتي'!$F:$F,"<>")-SUMIFS('POWER زفتي'!$D:$D,'POWER زفتي'!$C:$C,$A11,'POWER زفتي'!$G:$G,"<>",'POWER زفتي'!$F:$F,"")) -> 0 | M11: =IF($A11="","",SUMIFS('احمد المنوفي'!$D:$D,'احمد المنوفي'!$C:$C,$A11,'احمد المنوفي'!$F:$F,"<>")-SUMIFS('احمد المنوفي'!$D:$D,'احمد المنوفي'!$C:$C,$A11,'احمد المنوفي'!$G:$G,"<>",'احمد المنوفي'!$F:$F,"")) -> 0 | N11: =IF($A11="","",SUMIFS(السفير!$D:$D,السفير!$C:$C,$A11,السفير!$F:$F,"<>")-SUMIFS(السفير!$D:$D,السفير!$C:$C,$A11,السفير!$G:$G,"<>",السفير!$F:$F,"")) -> 0 | O11: =IF($A11="","",SUMIFS(العالمي!$D:$D,العالمي!$C:$C,$A11,العالمي!$F:$F,"<>")-SUMIFS(العالمي!$D:$D,العالمي!$C:$C,$A11,العالمي!$G:$G,"<>",العالمي!$F:$F,"")) -> 0 | P11: =IF($A11="","",SUMIFS('باهي التركي'!$D:$D,'باهي التركي'!$C:$C,$A11,'باهي التركي'!$F:$F,"<>")-SUMIFS('باهي التركي'!$D:$D,'باهي التركي'!$C:$C,$A11,'باهي التركي'!$G:$G,"<>",'باهي التركي'!$F:$F,"")) -> 12 | Q11: =IF($A11="","",SUMIFS('توتي دماص'!$D:$D,'توتي دماص'!$C:$C,$A11,'توتي دماص'!$F:$F,"<>")-SUMIFS('توتي دماص'!$D:$D,'توتي دماص'!$C:$C,$A11,'توتي دماص'!$G:$G,"<>",'توتي دماص'!$F:$F,"")) -> 0 | R11: =IF($A11="","",SUMIFS('رضا محمد'!$D:$D,'رضا محمد'!$C:$C,$A11,'رضا محمد'!$F:$F,"<>")-SUMIFS('رضا محمد'!$D:$D,'رضا محمد'!$C:$C,$A11,'رضا محمد'!$G:$G,"<>",'رضا محمد'!$F:$F,"")) -> 0 | S11: =IF($A11="","",SUMIFS('زومبي العشري'!$D:$D,'زومبي العشري'!$C:$C,$A11,'زومبي العشري'!$F:$F,"<>")-SUMIFS('زومبي العشري'!$D:$D,'زومبي العشري'!$C:$C,$A11,'زومبي العشري'!$G:$G,"<>",'زومبي العشري'!$F:$F,"")) -> 0 | T11: =IF($A11="","",SUMIFS('محمد عرابي'!$D:$D,'محمد عرابي'!$C:$C,$A11,'محمد عرابي'!$F:$F,"<>")-SUMIFS('محمد عرابي'!$D:$D,'محمد عرابي'!$C:$C,$A11,'محمد عرابي'!$G:$G,"<>",'محمد عرابي'!$F:$F,"")) -> 0 | U11: =IF($A11="","",SUMIFS('عم جمال'!$D:$D,'عم جمال'!$C:$C,$A11,'عم جمال'!$F:$F,"<>")-SUMIFS('عم جمال'!$D:$D,'عم جمال'!$C:$C,$A11,'عم جمال'!$G:$G,"<>",'عم جمال'!$F:$F,"")) -> 0 | V11: =IF($A11="","",SUMIFS('فاير سيليكت'!$D:$D,'فاير سيليكت'!$C:$C,$A11,'فاير سيليكت'!$F:$F,"<>")-SUMIFS('فاير سيليكت'!$D:$D,'فاير سيليكت'!$C:$C,$A11,'فاير سيليكت'!$G:$G,"<>",'فاير سيليكت'!$F:$F,"")) -> 0 | W11: =IF($A11="","",SUMIFS(فرانكو!$D:$D,فرانكو!$C:$C,$A11,فرانكو!$F:$F,"<>")-SUMIFS(فرانكو!$D:$D,فرانكو!$C:$C,$A11,فرانكو!$G:$G,"<>",فرانكو!$F:$F,"")) -> 0 | X11: =IF($A11="","",SUMIFS('كريم بكر'!$D:$D,'كريم بكر'!$C:$C,$A11,'كريم بكر'!$F:$F,"<>")-SUMIFS('كريم بكر'!$D:$D,'كريم بكر'!$C:$C,$A11,'كريم بكر'!$G:$G,"<>",'كريم بكر'!$F:$F,"")) -> 0 | Y11: =IF($A11="","",SUMIFS(بفرا!$D:$D,بفرا!$C:$C,$A11,بفرا!$F:$F,"<>")-SUMIFS(بفرا!$D:$D,بفرا!$C:$C,$A11,بفرا!$G:$G,"<>",بفرا!$F:$F,"")) -> 0 | Z11: =IF($A11="","",SUMIFS('محل كوم النور'!$D:$D,'محل كوم النور'!$C:$C,$A11,'محل كوم النور'!$F:$F,"<>")-SUMIFS('محل كوم النور'!$D:$D,'محل كوم النور'!$C:$C,$A11,'محل كوم النور'!$G:$G,"<>",'محل كوم النور'!$F:$F,"")) -> 0 | AA11: =IF($A11="","",SUMIFS('محمد النجار'!$D:$D,'محمد النجار'!$C:$C,$A11,'محمد النجار'!$F:$F,"<>")-SUMIFS('محمد النجار'!$D:$D,'محمد النجار'!$C:$C,$A11,'محمد النجار'!$G:$G,"<>",'محمد النجار'!$F:$F,"")) -> 0 | AB11: =IF($A11="","",SUMIFS('محمود عبدالرسول'!$D:$D,'محمود عبدالرسول'!$C:$C,$A11,'محمود عبدالرسول'!$F:$F,"<>")-SUMIFS('محمود عبدالرسول'!$D:$D,'محمود عبدالرسول'!$C:$C,$A11,'محمود عبدالرسول'!$G:$G,"<>",'محمود عبدالرسول'!$F:$F,"")) -> 8 | AC11: =IF($A11="","",SUMIFS('مول المصطفي'!$D:$D,'مول المصطفي'!$C:$C,$A11,'مول المصطفي'!$F:$F,"<>")-SUMIFS('مول المصطفي'!$D:$D,'مول المصطفي'!$C:$C,$A11,'مول المصطفي'!$G:$G,"<>",'مول المصطفي'!$F:$F,"")) -> 0 | AD11: =IF($A11="","",SUMIFS(مصانع!$D:$D,مصانع!$C:$C,$A11,مصانع!$F:$F,"<>")-SUMIFS(مصانع!$D:$D,مصانع!$C:$C,$A11,مصانع!$G:$G,"<>",مصانع!$F:$F,"")) -> 0 | AE11: =IF($A11="","",SUM(B11:AD11)) -> 56 | AF11: شروال وايد ليج | AG11: 96 | AH11: =IF(OR($A11="",AG11=""),"",AG11-AE11) -> 40 | AI11: 330 | AJ11: =IF(OR($A11="",AH11=""),"",AH11*AI11) -> 13200
A12: B06 | B12: =IF($A12="","",SUMIFS('4K حموده'!$D:$D,'4K حموده'!$C:$C,$A12,'4K حموده'!$F:$F,"<>")-SUMIFS('4K حموده'!$D:$D,'4K حموده'!$C:$C,$A12,'4K حموده'!$G:$G,"<>",'4K حموده'!$F:$F,"")) -> 0 | C12: =IF($A12="","",SUMIFS('مكتب القاضي'!$D:$D,'مكتب القاضي'!$C:$C,$A12,'مكتب القاضي'!$F:$F,"<>")-SUMIFS('مكتب القاضي'!$D:$D,'مكتب القاضي'!$C:$C,$A12,'مكتب القاضي'!$G:$G,"<>",'مكتب القاضي'!$F:$F,"")) -> 1 | D12: =IF($A12="","",SUMIFS(الاتشو!$D:$D,الاتشو!$C:$C,$A12,الاتشو!$F:$F,"<>")-SUMIFS(الاتشو!$D:$D,الاتشو!$C:$C,$A12,الاتشو!$G:$G,"<>",الاتشو!$F:$F,"")) -> 0 | E12: =IF($A12="","",SUMIFS('علاء بوم ارض النت'!$D:$D,'علاء بوم ارض النت'!$C:$C,$A12,'علاء بوم ارض النت'!$F:$F,"<>")-SUMIFS('علاء بوم ارض النت'!$D:$D,'علاء بوم ارض النت'!$C:$C,$A12,'علاء بوم ارض النت'!$G:$G,"<>",'علاء بوم ارض النت'!$F:$F,"")) -> 12 | F12: =IF($A12="","",SUMIFS('كيمو ميت ابو خالد'!$D:$D,'كيمو ميت ابو خالد'!$C:$C,$A12,'كيمو ميت ابو خالد'!$F:$F,"<>")-SUMIFS('كيمو ميت ابو خالد'!$D:$D,'كيمو ميت ابو خالد'!$C:$C,$A12,'كيمو ميت ابو خالد'!$G:$G,"<>",'كيمو ميت ابو خالد'!$F:$F,"")) -> 0 | G12: =IF($A12="","",SUMIFS(KAZO!$D:$D,KAZO!$C:$C,$A12,KAZO!$F:$F,"<>")-SUMIFS(KAZO!$D:$D,KAZO!$C:$C,$A12,KAZO!$G:$G,"<>",KAZO!$F:$F,"")) -> 0 | H12: =IF($A12="","",SUMIFS(LAFY!$D:$D,LAFY!$C:$C,$A12,LAFY!$F:$F,"<>")-SUMIFS(LAFY!$D:$D,LAFY!$C:$C,$A12,LAFY!$G:$G,"<>",LAFY!$F:$F,"")) -> 0 | I12: =IF($A12="","",SUMIFS('POINT زفتي (جديد)'!$D:$D,'POINT زفتي (جديد)'!$C:$C,$A12,'POINT زفتي (جديد)'!$F:$F,"<>")-SUMIFS('POINT زفتي (جديد)'!$D:$D,'POINT زفتي (جديد)'!$C:$C,$A12,'POINT زفتي (جديد)'!$G:$G,"<>",'POINT زفتي (جديد)'!$F:$F,"")) -> 0 | J12: =IF($A12="","",SUMIFS('POINT سعد زغلول (قديم)'!$D:$D,'POINT سعد زغلول (قديم)'!$C:$C,$A12,'POINT سعد زغلول (قديم)'!$F:$F,"<>")-SUMIFS('POINT سعد زغلول (قديم)'!$D:$D,'POINT سعد زغلول (قديم)'!$C:$C,$A12,'POINT سعد زغلول (قديم)'!$G:$G,"<>",'POINT سعد زغلول (قديم)'!$F:$F,"")) -> 0 | K12: =IF($A12="","",SUMIFS('POWER ارض النت'!$D:$D,'POWER ارض النت'!$C:$C,$A12,'POWER ارض النت'!$F:$F,"<>")-SUMIFS('POWER ارض النت'!$D:$D,'POWER ارض النت'!$C:$C,$A12,'POWER ارض النت'!$G:$G,"<>",'POWER ارض النت'!$F:$F,"")) -> 8 | L12: =IF($A12="","",SUMIFS('POWER زفتي'!$D:$D,'POWER زفتي'!$C:$C,$A12,'POWER زفتي'!$F:$F,"<>")-SUMIFS('POWER زفتي'!$D:$D,'POWER زفتي'!$C:$C,$A12,'POWER زفتي'!$G:$G,"<>",'POWER زفتي'!$F:$F,"")) -> 4 | M12: =IF($A12="","",SUMIFS('احمد المنوفي'!$D:$D,'احمد المنوفي'!$C:$C,$A12,'احمد المنوفي'!$F:$F,"<>")-SUMIFS('احمد المنوفي'!$D:$D,'احمد المنوفي'!$C:$C,$A12,'احمد المنوفي'!$G:$G,"<>",'احمد المنوفي'!$F:$F,"")) -> 0 | N12: =IF($A12="","",SUMIFS(السفير!$D:$D,السفير!$C:$C,$A12,السفير!$F:$F,"<>")-SUMIFS(السفير!$D:$D,السفير!$C:$C,$A12,السفير!$G:$G,"<>",السفير!$F:$F,"")) -> 0 | O12: =IF($A12="","",SUMIFS(العالمي!$D:$D,العالمي!$C:$C,$A12,العالمي!$F:$F,"<>")-SUMIFS(العالمي!$D:$D,العالمي!$C:$C,$A12,العالمي!$G:$G,"<>",العالمي!$F:$F,"")) -> 0 | P12: =IF($A12="","",SUMIFS('باهي التركي'!$D:$D,'باهي التركي'!$C:$C,$A12,'باهي التركي'!$F:$F,"<>")-SUMIFS('باهي التركي'!$D:$D,'باهي التركي'!$C:$C,$A12,'باهي التركي'!$G:$G,"<>",'باهي التركي'!$F:$F,"")) -> 8 | Q12: =IF($A12="","",SUMIFS('توتي دماص'!$D:$D,'توتي دماص'!$C:$C,$A12,'توتي دماص'!$F:$F,"<>")-SUMIFS('توتي دماص'!$D:$D,'توتي دماص'!$C:$C,$A12,'توتي دماص'!$G:$G,"<>",'توتي دماص'!$F:$F,"")) -> 0 | R12: =IF($A12="","",SUMIFS('رضا محمد'!$D:$D,'رضا محمد'!$C:$C,$A12,'رضا محمد'!$F:$F,"<>")-SUMIFS('رضا محمد'!$D:$D,'رضا محمد'!$C:$C,$A12,'رضا محمد'!$G:$G,"<>",'رضا محمد'!$F:$F,"")) -> 6 | S12: =IF($A12="","",SUMIFS('زومبي العشري'!$D:$D,'زومبي العشري'!$C:$C,$A12,'زومبي العشري'!$F:$F,"<>")-SUMIFS('زومبي العشري'!$D:$D,'زومبي العشري'!$C:$C,$A12,'زومبي العشري'!$G:$G,"<>",'زومبي العشري'!$F:$F,"")) -> 0 | T12: =IF($A12="","",SUMIFS('محمد عرابي'!$D:$D,'محمد عرابي'!$C:$C,$A12,'محمد عرابي'!$F:$F,"<>")-SUMIFS('محمد عرابي'!$D:$D,'محمد عرابي'!$C:$C,$A12,'محمد عرابي'!$G:$G,"<>",'محمد عرابي'!$F:$F,"")) -> 0 | U12: =IF($A12="","",SUMIFS('عم جمال'!$D:$D,'عم جمال'!$C:$C,$A12,'عم جمال'!$F:$F,"<>")-SUMIFS('عم جمال'!$D:$D,'عم جمال'!$C:$C,$A12,'عم جمال'!$G:$G,"<>",'عم جمال'!$F:$F,"")) -> 0 | V12: =IF($A12="","",SUMIFS('فاير سيليكت'!$D:$D,'فاير سيليكت'!$C:$C,$A12,'فاير سيليكت'!$F:$F,"<>")-SUMIFS('فاير سيليكت'!$D:$D,'فاير سيليكت'!$C:$C,$A12,'فاير سيليكت'!$G:$G,"<>",'فاير سيليكت'!$F:$F,"")) -> 0 | W12: =IF($A12="","",SUMIFS(فرانكو!$D:$D,فرانكو!$C:$C,$A12,فرانكو!$F:$F,"<>")-SUMIFS(فرانكو!$D:$D,فرانكو!$C:$C,$A12,فرانكو!$G:$G,"<>",فرانكو!$F:$F,"")) -> 0 | X12: =IF($A12="","",SUMIFS('كريم بكر'!$D:$D,'كريم بكر'!$C:$C,$A12,'كريم بكر'!$F:$F,"<>")-SUMIFS('كريم بكر'!$D:$D,'كريم بكر'!$C:$C,$A12,'كريم بكر'!$G:$G,"<>",'كريم بكر'!$F:$F,"")) -> 0 | Y12: =IF($A12="","",SUMIFS(بفرا!$D:$D,بفرا!$C:$C,$A12,بفرا!$F:$F,"<>")-SUMIFS(بفرا!$D:$D,بفرا!$C:$C,$A12,بفرا!$G:$G,"<>",بفرا!$F:$F,"")) -> 0 | Z12: =IF($A12="","",SUMIFS('محل كوم النور'!$D:$D,'محل كوم النور'!$C:$C,$A12,'محل كوم النور'!$F:$F,"<>")-SUMIFS('محل كوم النور'!$D:$D,'محل كوم النور'!$C:$C,$A12,'محل كوم النور'!$G:$G,"<>",'محل كوم النور'!$F:$F,"")) -> 0 | AA12: =IF($A12="","",SUMIFS('محمد النجار'!$D:$D,'محمد النجار'!$C:$C,$A12,'محمد النجار'!$F:$F,"<>")-SUMIFS('محمد النجار'!$D:$D,'محمد النجار'!$C:$C,$A12,'محمد النجار'!$G:$G,"<>",'محمد النجار'!$F:$F,"")) -> 0 | AB12: =IF($A12="","",SUMIFS('محمود عبدالرسول'!$D:$D,'محمود عبدالرسول'!$C:$C,$A12,'محمود عبدالرسول'!$F:$F,"<>")-SUMIFS('محمود عبدالرسول'!$D:$D,'محمود عبدالرسول'!$C:$C,$A12,'محمود عبدالرسول'!$G:$G,"<>",'محمود عبدالرسول'!$F:$F,"")) -> 0 | AC12: =IF($A12="","",SUMIFS('مول المصطفي'!$D:$D,'مول المصطفي'!$C:$C,$A12,'مول المصطفي'!$F:$F,"<>")-SUMIFS('مول المصطفي'!$D:$D,'مول المصطفي'!$C:$C,$A12,'مول المصطفي'!$G:$G,"<>",'مول المصطفي'!$F:$F,"")) -> 0 | AD12: =IF($A12="","",SUMIFS(مصانع!$D:$D,مصانع!$C:$C,$A12,مصانع!$F:$F,"<>")-SUMIFS(مصانع!$D:$D,مصانع!$C:$C,$A12,مصانع!$G:$G,"<>",مصانع!$F:$F,"")) -> 0 | AE12: =IF($A12="","",SUM(B12:AD12)) -> 39 | AF12: ترنج انترلوك NR | AG12: 80 | AH12: =IF(OR($A12="",AG12=""),"",AG12-AE12) -> 41 | AI12: 800 | AJ12: =IF(OR($A12="",AH12=""),"",AH12*AI12) -> 32800
